Workbook

Sheet Cover
B1: BLACKLINE TAKE-PRIVATE LBO MODEL
B4: PREPARED FOR SPONSOR INVESTMENT COMMITTEE
B5: July 2026 | Illustrative | Prepared for Portfolio Purposes
B8: TRANSACTION SUMMARY | F8: RETURNS SUMMARY
B9: Entry Enterprise Value | D9: =Assumptions!C15 -> 2282.5334 | F9: Exit Enterprise Value | H9: =Returns!G12 -> 4172.9966
B10: Entry Revenue | D10: =Assumptions!C10 -> 716.651 | F10: Exit Equity Value | H10: =Returns!G14 -> 3847.9594
B11: Entry EBITDA | D11: =Assumptions!C11 -> 185.146 | F11: MOIC | H11: =Returns!G17 -> 2.6611637
B12: Entry EV/EBITDA | D12: =Assumptions!C14 -> 12.328289 | F12: Gross IRR | H12: =Returns!G18 -> 0.2162261
B13: Debt Raised | D13: =Assumptions!C24 -> 925.73 | F13: DEBT PAYDOWN | H13: =Assumptions!C24-'Debt Schedule'!G9 -> 575.69283
B14: SPONSOR EQUITY | D14: ='Sources and Uses '!C12 -> 1445.9687
B16: INVESTMENT THESIS | F16: KEY RISKS
B17: • Mission-critical financial close automation platform embedded within enterprise accounting workflows, resulting in high switching costs and durable customer relationships. • Attractive operating leverage opportunity through sales efficiency improvements, disciplined cost management and platform scalability. • Highly recurring subscription revenue model generating predictable cash flows and strong free cash flow conversion. • Opportunity to acquire a high-quality software asset at an attractive valuation relative to historical software transaction multiples. • Multiple potential exit pathways including sponsor-to-sponsor sale, strategic acquisition or public market re-listing. | F17: • Enterprise software spending slowdown could negatively impact revenue growth and customer expansion activity. • Failure to achieve planned EBITDA margin expansion could reduce sponsor returns. • Competitive pressure from ERP vendors and adjacent software providers could affect pricing power and customer retention. • Higher interest rates may reduce deleveraging capacity and equity returns. • Exit multiple compression could materially reduce MOIC and IRR outcomes.
B19: Sources: PitchBook | SEC Filings | Company IR Materials | Public Trading Comparables| Management Estimates

Sheet Assumptions
A1: BLACKLINE TAKE-PRIVATE LBO — ASSUMPTIONS
A3: Item | B3: Entity / PBID | C3: Value | D3: Units | E3: Source | F3: Confidence | G3: Notes
A4: DEAL DATE / MODEL SETUP | J4: Metric | K4: Value
A5: Model Date | B5: 58453-75 | C5: 46205 | D5: Date | E5: Model Convention | F5: H | G5: Model valuation date | J5: Entry EV | K5: =C15 -> 2282.5334
A6: Currency | B6: 58453-75 | C6: USD | D6: Text | E6: Model Convention | F6: H | G6: Reporting currency | J6: Entry EV / EBITDA | K6: =C14 -> 12.328289
A7: Figures Presented In | B7: 58453-75 | C7: $mm | D7: Text | E7: Model Convention | F7: H | G7: Financial unit convention | J7: Debt % Capital | K7: ='Sources and Uses '!C16 -> 0.39032361
J8: Equity % Capital | K8: ='Sources and Uses '!C17 -> 0.60967639
A9: TRANSACTION ASSUMPTIONS
A10: Entry Revenue | B10: 58453-75 | C10: 716.651 | D10: $mm | E10: PitchBook / Company Filings | F10: H | G10: FY2026E revenue (static value; source:PitchBook, pulled July 2026) | J10: Exit EV / EBITDA | K10: =C14 -> 12.328289
A11: Entry EBITDA | B11: 58453-75 | C11: 185.146 | D11: $mm | E11: PitchBook / Company Filings | F11: H | G11: Adjusted EBITDA proxy (static value; source:PitchBook, pulled July 2026) | J11: Hold Period (Years) | K11: 5
A12: EBITDA Margin | B12: 58453-75 | C12: =C11/C10 -> 0.2583489 | D12: % | E12: Formula | F12: H | G12: EBITDA / Revenue
A13: Entry EV / Revenue | B13: 58453-75 | C13: 3.185 | D13: x | E13: PitchBook Market Data | F13: H/M | G13: SaaS transaction comps
A14: Entry EV / EBITDA | B14: 58453-75 | C14: =C15/C11 -> 12.328289 | D14: x | E14: Formula | F14: H | G14: Derived valuation multiple
A15: Entry Enterprise Value | B15: 58453-75 | C15: =C10*C13 -> 2282.5334 | D15: $mm | E15: Formula | F15: H | G15: Implied purchase EV
A17: USES ASSUMPTIONS
A18: Purchase Enterprise Value | B18: 58453-75 | C18: =C15 -> 2282.5334 | D18: $mm | E18: Formula | F18: H | G18: Purchase consideration
A19: Transaction Fees | B19: 58453-75 | C19: 0.02 | D19: % EV | E19: Sponsor Assumption | F19: M | G19: Legal, advisory, diligence
A20: Financing Fees | B20: 58453-75 | C20: 0.02 | D20: % Debt | E20: LevFin Market Data | F20: M | G20: Debt issuance fees
A22: FINANCING ASSUMPTIONS
A23: Debt / EBITDA | B23: 58453-75 | C23: 5 | D23: x | E23: PitchBook LBO Comps | F23: H/M | G23: Sponsor leverage
A24: New Debt | B24: 58453-75 | C24: =C11*C23 -> 925.73 | D24: $mm | E24: Formula | F24: H | G24: Debt raised at close
A25: Cash Interest Rate | B25: 58453-75 | C25: 0.095 | D25: % | E25: LevFin Market Data | F25: M | G25: SOFR + spread
A26: Sponsor Equity | B26: 58453-75 | C26: ='Sources and Uses '!C12 -> 1445.9687 | D26: $mm | E26: Formula | F26: H | G26: Equity check
A27: Minimum Cash Balance | B27: 58453-75 | C27: 25 | D27: $mm | E27: Credit Agreement Convention | F27: M | G27: Liquidity floor retained on balance sheet
A29: OUTPUT CHECKS
A30: Sources Less Uses | B30: 58453-75 | C30: ='Sources and Uses '!C25 -> 0 | D30: $mm | E30: Formula | F30: H | G30: Must equal zero
A31: Balance Check | B31: 58453-75 | C31: =IF(ABS(C30)<0.01,"OK","ERROR") -> OK | D31: Text | E31: Formula | F31: H | G31: Return OK or ERROR

Sheet Sources
A1: BLACKLINE TAKE-PRIVATE LBO – SOURCES
A3: METRIC | B3: VALUE | C3: PERIOD | D3: SOURCE | E3: METHODOLOGY | F3: NOTES
A5: COMPANY OVERVIEW
A6: Company | B6: BlackLine | C6: Current | D6: PitchBook | E6: Company Profile | F6: Target Company
A7: Ticker | B7: BL | C7: Current | D7: PitchBook | E7: Company Profile | F7: NYSE Listed
A8: Sector | B8: Software | C8: Current | D8: PitchBook | E8: Company Profile | F8: Enterprise Software
A9: Industry | B9: Financial Software | C9: Current | D9: PitchBook | E9: Company Profile | F9: Office of CFO Software
A10: Headquarters | B10: Los Angeles, CA | C10: Current | D10: PitchBook | E10: Company Profile | F10: United States
A11: Currency | B11: USD | C11: Current | D11: Model Convention | E11: Standardized | F11: USD ($mm)
A13: OPERATING METRICS
A14: Revenue | B14: 716.651 | C14: NTM | D14: PitchBook Excel Plugin | E14: Reported Total Revenue | F14: Underwriting Revenue
A15: EBITDA | B15: 185.146 | C15: NTM | D15: PitchBook Excel Plugin | E15: Normalized EBITDA | F15: Underwriting EBITDA
A16: EBITDA Margin | B16: 0.2583489 | C16: NTM | D16: Calculated | E16: EBITDA / Revenue | F16: Derived Metric
A17: EV / Revenue | B17: 3.185 | C17: NTM | D17: PitchBook | E17: Enterprise Value / Revenue | F17: Entry Multiple
A18: EV / EBITDA | B18: 12.328289 | C18: NTM | D18: PitchBook | E18: Enterprise Value / EBITDA | F18: Entry Multiple
A19: Enterprise Value | B19: 2282.5334 | C19: Entry | D19: Calculated | E19: Revenue × EV / Revenue | F19: Purchase Price
A21: TRANSACTION ASSUMPTION
A22: Entry EV / Revenue | B22: 3.185 | C22: Entry | D22: Sponsor Underwriting | E22: Public Comp Benchmarking | F22: Purchase Multiple
A23: Entry EV / EBITDA | B23: 12.328289 | C23: Entry | D23: Sponsor Underwriting | E23: Public Comp Benchmarking | F23: Purchase Multiple
A24: Exit EV / EBITDA | B24: 12.328289 | C24: Exit | D24: Sponsor Underwriting | E24: Multiple Neutral Exit | F24: No Expansion Assumed
A25: Hold Period | B25: 5 Years | C25: Model | D25: Sponsor Underwriting | E25: Standard PE Hold | F25: 2026-2031
A26: Control Premium | B26: 0.3 | C26: Entry | D26: Market Convention | E26: Typical Take-Private Premium | F26: Illustrative
A28: FINANCING ASSUMPTION
A29: Debt / EBITDA | B29: 5 | C29: Entry | D29: LevFin Market | E29: Market Leverage Capacity | F29: Senior Debt
A30: Interest Rate | B30: 0.095 | C30: Entry | D30: LevFin Market | E30: SOFR + Credit Spread | F30: Cash Interest
A31: Transaction Fees | B31: 0.02 | C31: Entry | D31: Market Convention | E31: % of Purchase EV | F31: Advisory Fees
A32: Financing Fees | B32: 0.02 | C32: Entry | D32: Market Convention | E32: % of Debt Raised | F32: OID + Debt Fees
A33: Mandatory Amortization | B33: 0.01 | C33: Annual | D33: Credit Agreement Convention | E33: Annual Sweep | F33: Simplified Assumption
A35: PUBLIC COMPANY COMPARABLE
A36: COMPANY | B36: TICKER | C36: SOURCE | D36: RATIONALE
A37: BlackLine | B37: BL | C37: PitchBook | D37: Target Company
A38: BILL Holdings | B38: BILL | C38: PitchBook | D38: Adjacent Financial Automation
A39: Freshworks | B39: FRSH | C39: PitchBook | D39: SaaS Benchmark
A40: Sprout Social | B40: SPT | C40: PitchBook | D40: Mid-Cap SaaS Benchmark
A41: Q2 Holdings | B41: QTWO | C41: PitchBook | D41: Financial Software Comparable
A43: DATA SOURCES
A44: Source | B44: Usage
A45: PitchBook | B45: Market Data and trading multiples
A46: SEC Filing | B46: Historical Financials
A47: Company Investor Relation | B47: Business Profile and Strategy
...

Sheet Sources and Uses 
A1: BLACKLINE TAKE PRIVATE -LBO – SOURCES AND USES
A3: item | B3: Reference | C3: Value | D3: Units | E3: Source | F3: Notes
A4: USES OF FUNDS
A5: Purchase Enterprise Value | B5: Assumptions | C5: =Assumptions!C18 -> 2282.5334 | D5: $mm | E5: Assumptions | F5: Purchase Consideration
A6: Transaction Fees | B6: Assumptions | C6: =C5*Assumptions!C19 -> 45.650669 | D6: $mm | E6: Assumptions | F6: Legal, Advisory, diligence
A7: Financing Fees | B7: Assumptions | C7: =Assumptions!C24*Assumptions!C20 -> 18.5146 | D7: $mm | E7: Assumptions | F7: Debt Issuance Costs
A8: Total Uses | B8: Formula | C8: =SUM(C5:C7)+C9 -> 2371.6987 | D8: $mm | E8: =B8 -> Formula | F8: Total Transaction Costs
A9: Cash to Balance Sheet | B9: Assumptions | C9: =Assumptions!C27 -> 25 | D9: $mm | E9: Assumptions | F9: Minimum liquidity funded at close
A10: SOURCES OF FUNDS
A11: New Debt | B11: Assumptions | C11: =Assumptions!C24 -> 925.73 | D11: $mm | E11: Assumptions | F11: Acquisition Financing
A12: Sponsor Equity | B12: Plug | C12: =C8-C11 -> 1445.9687 | D12: $mm | E12: Formula | F12: Equity Contribution
A13: Total Sources | B13: Formula | C13: =SUM(C11:C12) -> 2371.6987 | D13: $mm | E13: Formula | F13: Total Funding
A15: TRANSACTION SUMMARY
A16: Debt % Of Capital | C16: =C11/C13 -> 0.39032361
A17: Equity % of Capital | C17: =C12/C13 -> 0.60967639
A18: Equity Check ($mm) | C18: =C13-C8 -> 0
A19: Equity Check Status | C19: =IF(ABS(C18)<0.01,"PASS","FAIL") -> PASS
A20: Entry EV/EBITDA | C20: =Assumptions!C14 -> 12.328289
A21: Entry EV /REVENUE | C21: =Assumptions!C13 -> 3.185
A22: DEBT/EBITDA | C22: =Assumptions!C23 -> 5
A24: BALANCE CHECK
A25: Sources Less Uses | C25: =C13-C8 -> 0
A26: Model Check | C26: =IF(ABS(C25)<0.01,"OK","ERROR") -> OK

Sheet Operating Model
A1: BLACKLINE TAKE - PRIVATE LBO – OPERATING MODEL
A3: Fiscal Year | B3: 2026 E | C3: 2027 E | D3: 2028 E | E3: 2029 E | F3: 2030 E | G3: 2031 E
A4: REVENUE BUILD
A5: Revenue | B5: =Assumptions!C10 -> 716.651 | C5: =B5*(1+C6) -> 773.98308 | D5: =C5*(1+D6) -> 839.77164 | E5: =D5*(1+E6) -> 915.35109 | F5: =E5*(1+F6) -> 988.57918 | G5: =F5*(1+G6) -> 1057.7797
A6: Revenue Growth | C6: 0.08 | D6: 0.085 | E6: 0.09 | F6: 0.08 | G6: 0.07
A7: PROFITABILITY
A8: EBITDA Margin | B8: =Assumptions!C12 -> 0.2583489 | C8: 0.27 | D8: 0.285 | E8: 0.3 | F8: 0.31 | G8: 0.32
A9: EBITDA | B9: =B5*B8 -> 185.146 | C9: =C5*C8 -> 208.97543 | D9: =D5*D8 -> 239.33492 | E9: =E5*E8 -> 274.60533 | F9: =F5*F8 -> 306.45954 | G9: =G5*G8 -> 338.48951
A10: D&A/ Revenue | B10: 0.04 | C10: 0.04 | D10: 0.04 | E10: 0.04 | F10: 0.04 | G10: 0.04
A11: D&A | B11: =B5*B10 -> 28.66604 | C11: =C5*C10 -> 30.959323 | D11: =D5*D10 -> 33.590866 | E11: =E5*E10 -> 36.614044 | F11: =F5*F10 -> 39.543167 | G11: =G5*G10 -> 42.311189
A12: EBIT | B12: =B9-B11 -> 156.47996 | C12: =C9-C11 -> 178.01611 | D12: =D9-D11 -> 205.74405 | E12: =E9-E11 -> 237.99128 | F12: =F9-F11 -> 266.91638 | G12: =G9-G11 -> 296.17832
A13: TAXES
A14: Cash Tax Rate | B14: 0.25 | C14: 0.25 | D14: 0.25 | E14: 0.25 | F14: 0.25 | G14: 0.25
A15: Cash Taxes | B15: =MAX(0,B12*B14) -> 39.11999 | C15: =MAX(0,C12*C14) -> 44.504027 | D15: =MAX(0,D12*D14) -> 51.436013 | E15: =MAX(0,E12*E14) -> 59.497821 | F15: =MAX(0,F12*F14) -> 66.729094 | G15: =MAX(0,G12*G14) -> 74.04458
A16: NOPAT | B16: =B12-B15 -> 117.35997 | C16: =C12-C15 -> 133.51208 | D16: =D12-D15 -> 154.30804 | E16: =E12-E15 -> 178.49346 | F16: =F12-F15 -> 200.18728 | G16: =G12-G15 -> 222.13374
A17: FREE CASH FLOW
A18: Plus: D&A | B18: =B11 -> 28.66604 | C18: =C11 -> 30.959323 | D18: =D11 -> 33.590866 | E18: =E11 -> 36.614044 | F18: =F11 -> 39.543167 | G18: =G11 -> 42.311189
A19: Less: Capex/Revenue | B19: 0.03 | C19: 0.03 | D19: 0.03 | E19: 0.03 | F19: 0.03 | G19: 0.03
A20: Less: Capex | B20: =B5*B19 -> 21.49953 | C20: =C5*C19 -> 23.219492 | D20: =D5*D19 -> 25.193149 | E20: =E5*E19 -> 27.460533 | F20: =F5*F19 -> 29.657375 | G20: =G5*G19 -> 31.733392
A21: Less: Change in NWC/ Revenue | B21: 0.01 | C21: 0.01 | D21: 0.01 | E21: 0.01 | F21: 0.01 | G21: 0.01
A22: Less: Change in NWC | B22: =B5*B21 -> 7.16651 | C22: =C5*C21 -> 7.7398308 | D22: =D5*D21 -> 8.3977164 | E22: =E5*E21 -> 9.1535109 | F22: =F5*F21 -> 9.8857918 | G22: =G5*G21 -> 10.577797
A23: Unlevered Free Cash Flow (reference only — see Debt Schedule) | B23: =B16+B18-B20-B22 -> 117.35997 | C23: =C16+C18-C20-C22 -> 133.51208 | D23: =D16+D18-D20-D22 -> 154.30804 | E23: =E16+E18-E20-E22 -> 178.49346 | F23: =F16+F18-F20-F22 -> 200.18728 | G23: =G16+G18-G20-G22 -> 222.13374
A25: RULE OF 40
A26: Revenue Growth + EBITDA Margin | B26: n/a | C26: =C6+C8 -> 0.35 | D26: =D6+D8 -> 0.37 | E26: =E6+E8 -> 0.39 | F26: =F6+F8 -> 0.39 | G26: =G6+G8 -> 0.39

Sheet Debt Schedule
A1: BLACKLINE TAKE-PRIVATE LBO – DEBT SCHEDULE
A3: Fiscal Year | B3: 2026 E | C3: 2027 E | D3: 2028 E | E3: 2029 E | F3: 2030 E | G3: 2031 E
A4: DEBT BALANCE
A5: Beginning Debt | B5: =0 -> 0 | C5: =B9 -> 890.07099 | D5: =C9 -> 836.07576 | E5: =D9 -> 757.97736 | F5: =E9 -> 650.91001 | G5: =F9 -> 515.59097
A6: New Debt Issued | B6: =Assumptions!C24 -> 925.73 | C6: =0 -> 0 | D6: =0 -> 0 | E6: =0 -> 0 | F6: =0 -> 0 | G6: =0 -> 0
A7: Mandatory Amortization | B7: =B12*Sources!$B$33 -> 9.2573 | C7: =C12*Sources!$B$33 -> 8.9007099 | D7: =D12*Sources!$B$33 -> 8.3607576 | E7: =E12*Sources!$B$33 -> 7.5797736 | F7: =F12*Sources!$B$33 -> 6.5091001 | G7: =G12*Sources!$B$33 -> 5.1559097
A8: Cash sweep | B8: =MAX(0,MIN(B15-Assumptions!$C$27,B12-B7)) -> 26.401708 | C8: =MAX(0,MIN(C15-Assumptions!$C$27,C12-C7)) -> 45.094523 | D8: =MAX(0,MIN(D15-Assumptions!$C$27,D12-D7)) -> 69.737641 | E8: =MAX(0,MIN(E15-Assumptions!$C$27,E12-E7)) -> 99.487576 | F8: =MAX(0,MIN(F15-Assumptions!$C$27,F12-F7)) -> 128.80994 | G8: =MAX(0,MIN(G15-Assumptions!$C$27,G12-G7)) -> 160.39788
A9: Ending Debt | B9: =B12-B7-B8 -> 890.07099 | C9: =C12-C7-C8 -> 836.07576 | D9: =D12-D7-D8 -> 757.97736 | E9: =E12-E7-E8 -> 650.91001 | F9: =F12-F7-F8 -> 515.59097 | G9: =G12-G7-G8 -> 350.03717
A11: INTEREST EXPENSE
A12: Debt Balance for Interest | B12: =B5+B6 -> 925.73 | C12: =C5+C6 -> 890.07099 | D12: =D5+D6 -> 836.07576 | E12: =E5+E6 -> 757.97736 | F12: =F5+F6 -> 650.91001 | G12: =G5+G6 -> 515.59097
A13: Cash Interest Rate | B13: =Assumptions!C25 -> 0.095 | C13: =Assumptions!C25 -> 0.095 | D13: =Assumptions!C25 -> 0.095 | E13: =Assumptions!C25 -> 0.095 | F13: =Assumptions!C25 -> 0.095 | G13: =Assumptions!C25 -> 0.095
A14: Interest Expense | B14: =B12*B13 -> 87.94435 | C14: =C12*C13 -> 84.556744 | D14: =D12*D13 -> 79.427197 | E14: =E12*E13 -> 72.007849 | F14: =F12*F13 -> 61.836451 | G14: =G12*G13 -> 48.981142
A15: Levered Free Cash Flow (from row 29) | B15: =B28 -> 51.401708 | C15: =C28 -> 70.094523 | D15: =D28 -> 94.737641 | E15: =E28 -> 124.48758 | F15: =F28 -> 153.80994 | G15: =G28 -> 185.39788
A16: CREDIT METRICS
A17: EBITDA | B17: ='Operating Model'!B9 -> 185.146 | C17: ='Operating Model'!C9 -> 208.97543 | D17: ='Operating Model'!D9 -> 239.33492 | E17: ='Operating Model'!E9 -> 274.60533 | F17: ='Operating Model'!F9 -> 306.45954 | G17: ='Operating Model'!G9 -> 338.48951
A18: Total Debt / EBITDA | B18: =B9/B17 -> 4.8074006 | C18: =C9/C17 -> 4.0008328 | D18: =D9/D17 -> 3.1670154 | E18: =E9/E17 -> 2.3703474 | F18: =F9/F17 -> 1.6824112 | G18: =G9/G17 -> 1.0341153
A19: Interest Coverage | B19: =B17/B14 -> 2.1052632 | C19: =C17/C14 -> 2.4714224 | D19: =D17/D14 -> 3.0132615 | E19: =E17/E14 -> 3.8135471 | F19: =F17/F14 -> 4.9559692 | G19: =G17/G14 -> 6.9106088
A21: Ending Debt Check | B21: =IF(MIN(B9:G9)>=0,"PASS","FAIL") -> PASS
A23: LEVERED TAX BUILD
A24: EBIT | B24: ='Operating Model'!B12 -> 156.47996 | C24: ='Operating Model'!C12 -> 178.01611 | D24: ='Operating Model'!D12 -> 205.74405 | E24: ='Operating Model'!E12 -> 237.99128 | F24: ='Operating Model'!F12 -> 266.91638 | G24: ='Operating Model'!G12 -> 296.17832
A25: Less: Interest Expense | B25: =-B14 -> -87.94435 | C25: =-C14 -> -84.556744 | D25: =-D14 -> -79.427197 | E25: =-E14 -> -72.007849 | F25: =-F14 -> -61.836451 | G25: =-G14 -> -48.981142
A26: EBT | B26: =B24+B25 -> 68.53561 | C26: =C24+C25 -> 93.459364 | D26: =D24+D25 -> 126.31686 | E26: =E24+E25 -> 165.98343 | F26: =F24+F25 -> 205.07993 | G26: =G24+G25 -> 247.19718
A27: Levered Cash Taxes | B27: =MAX(0,B26*'Operating Model'!B14) -> 17.133902 | C27: =MAX(0,C26*'Operating Model'!C14) -> 23.364841 | D27: =MAX(0,D26*'Operating Model'!D14) -> 31.579214 | E27: =MAX(0,E26*'Operating Model'!E14) -> 41.495859 | F27: =MAX(0,F26*'Operating Model'!F14) -> 51.269982 | G27: =MAX(0,G26*'Operating Model'!G14) -> 61.799295
A28: Levered Free Cash Flow (post tax shield) | B28: =B26-B27+'Operating Model'!B11-'Operating Model'!B20-'Operating Model'!B22 -> 51.401708 | C28: =C26-C27+'Operating Model'!C11-'Operating Model'!C20-'Operating Model'!C22 -> 70.094523 | D28: =D26-D27+'Operating Model'!D11-'Operating Model'!D20-'Operating Model'!D22 -> 94.737641 | E28: =E26-E27+'Operating Model'!E11-'Operating Model'!E20-'Operating Model'!E22 -> 124.48758 | F28: =F26-F27+'Operating Model'!F11-'Operating Model'!F20-'Operating Model'!F22 -> 153.80994 | G28: =G26-G27+'Operating Model'!G11-'Operating Model'!G20-'Operating Model'!G22 -> 185.39788
A29: Memo: Annual Tax Shield Benefit | B29: ='Operating Model'!B15-B27 -> 21.986087 | C29: ='Operating Model'!C15-C27 -> 21.139186 | D29: ='Operating Model'!D15-D27 -> 19.856799 | E29: ='Operating Model'!E15-E27 -> 18.001962 | F29: ='Operating Model'!F15-F27 -> 15.459113 | G29: ='Operating Model'!G15-G27 -> 12.245285

Sheet Returns
A1: BLACKLINE TAKE - PRIVATE LBO – RETURNS ANALYSIS
A3: Fiscal Year | B3: 2026E | C3: 2027E | D3: 2028E | E3: 2029E | F3: 2030E | G3: 2031E
A4: ENTRY VALUATION
A5: Entry Enterprise Value | B5: =Assumptions!C15 -> 2282.5334
A6: Entry EBITDA | B6: =Assumptions!C11 -> 185.146
A7: Entry EV/EBITDA | B7: =B5/B6 -> 12.328289
A8: Sponsor Equity | B8: ='Sources and Uses '!C12 -> 1445.9687
A10: EXIT VALUATION
A11: Exit EBITDA | G11: ='Operating Model'!G9 -> 338.48951
A12: Exit Enterprise Value | G12: =G11*Assumptions!K10 -> 4172.9966
A13: Less : Net Debt (ending debt less cash) | G13: ='Debt Schedule'!G9-Assumptions!C27 -> 325.03717
A14: Exit Equity Value | G14: =G12-G13 -> 3847.9594
A16: RETURNS
A17: MOIC | G17: =G14/B8 -> 2.6611637
A18: GROSS IRR | G18: =G17^(1/Assumptions!K11)-1 -> 0.2162261

Sheet Valuation Bridge
A1: BLACKLINE TAKE-PRIVATE LBO – VALUATION BRIDGE
A3: Lever | B3: Value ($mm) | C3: % of Equity Gain
A4: Revenue Growth | B4: =('Operating Model'!G5-'Operating Model'!B5)*'Operating Model'!B8*Returns!B7 -> 1086.495 | C4: =B4/$B$9 -> 0.45233105
A5: Margin Expansion | B5: ='Operating Model'!G5*('Operating Model'!G8-'Operating Model'!B8)*Returns!B7 -> 803.96817 | C5: =B5/$B$9 -> 0.33470911
A6: Multiple Expansion | B6: =(Assumptions!K10-Returns!B7)*Returns!G11 -> 0 | C6: =IF($B$9=0,0,B6/$B$9) -> 0
A7: Deleveraging | B7: =Assumptions!C24-'Debt Schedule'!G9 -> 575.69283 | C7: =B7/$B$9 -> 0.23967321
A8: Transaction & Financing Fees | B8: =-('Sources and Uses '!C6+'Sources and Uses '!C7) -> -64.165269 | C8: =B8/$B$9 -> -0.026713371
A9: Total Equity Gain | B9: =Returns!G14-Returns!B8 -> 2401.9907 | C9: =1 -> 1
A10: Check | B10: =SUM(B4:B8)-B9 -> 0 | C10: =IF(ABS(B10)<0.1,"PASS","FAIL") -> PASS

Sheet Sensitivity
A1: BLACKLINE TAKE - PRIVATE LBO – SENSITIVITY TABLE
A3: TRANSACTION SUMMARY
A5: Entry EV/EBITDA | B5: =Returns!B7 -> 12.328289
A6: Exit EV/EBITDA | B6: =Assumptions!K10 -> 12.328289
A7: Revenue CAGR | B7: =('Operating Model'!G5/'Operating Model'!B5)^(1/Assumptions!K11)-1 -> 0.080979617
A8: EBITDA Margin Expansion | B8: ='Operating Model'!G8-'Operating Model'!B8 -> 0.061651097
A10: IRR SENSITIVITY MATRIX
A11: Exit Multiple↓/ Margin → | C11: 0.28 | D11: 0.3 | E11: 0.32 | F11: 0.34 | G11: 0.36
A12: 10.0x | C12: =((('Operating Model'!$G$5*C$11*VALUE(SUBSTITUTE($A12,"x","")))-Returns!$G$13)/Returns!$B$8)^(1/Assumptions!$K$11)-1 -> 0.12766962 | D12: =((('Operating Model'!$G$5*D$11*VALUE(SUBSTITUTE($A12,"x","")))-Returns!$G$13)/Returns!$B$8)^(1/Assumptions!$K$11)-1 -> 0.14521078 | E12: =((('Operating Model'!$G$5*E$11*VALUE(SUBSTITUTE($A12,"x","")))-Returns!$G$13)/Returns!$B$8)^(1/Assumptions!$K$11)-1 -> 0.16173875 | F12: =((('Operating Model'!$G$5*F$11*VALUE(SUBSTITUTE($A12,"x","")))-Returns!$G$13)/Returns!$B$8)^(1/Assumptions!$K$11)-1 -> 0.17737638 | G12: =((('Operating Model'!$G$5*G$11*VALUE(SUBSTITUTE($A12,"x","")))-Returns!$G$13)/Returns!$B$8)^(1/Assumptions!$K$11)-1 -> 0.19222483
A13: 11.0x | C13: =((('Operating Model'!$G$5*C$11*VALUE(SUBSTITUTE($A13,"x","")))-Returns!$G$13)/Returns!$B$8)^(1/Assumptions!$K$11)-1 -> 0.15193611 | D13: =((('Operating Model'!$G$5*D$11*VALUE(SUBSTITUTE($A13,"x","")))-Returns!$G$13)/Returns!$B$8)^(1/Assumptions!$K$11)-1 -> 0.16966209 | E13: =((('Operating Model'!$G$5*E$11*VALUE(SUBSTITUTE($A13,"x","")))-Returns!$G$13)/Returns!$B$8)^(1/Assumptions!$K$11)-1 -> 0.18637443 | F13: =((('Operating Model'!$G$5*F$11*VALUE(SUBSTITUTE($A13,"x","")))-Returns!$G$13)/Returns!$B$8)^(1/Assumptions!$K$11)-1 -> 0.2021949 | G13: =((('Operating Model'!$G$5*G$11*VALUE(SUBSTITUTE($A13,"x","")))-Returns!$G$13)/Returns!$B$8)^(1/Assumptions!$K$11)-1 -> 0.21722394
A14: 12.0x | C14: =((('Operating Model'!$G$5*C$11*VALUE(SUBSTITUTE($A14,"x","")))-Returns!$G$13)/Returns!$B$8)^(1/Assumptions!$K$11)-1 -> 0.17431496 | D14: =((('Operating Model'!$G$5*D$11*VALUE(SUBSTITUTE($A14,"x","")))-Returns!$G$13)/Returns!$B$8)^(1/Assumptions!$K$11)-1 -> 0.19222483 | E14: =((('Operating Model'!$G$5*E$11*VALUE(SUBSTITUTE($A14,"x","")))-Returns!$G$13)/Returns!$B$8)^(1/Assumptions!$K$11)-1 -> 0.20911901 | F14: =((('Operating Model'!$G$5*F$11*VALUE(SUBSTITUTE($A14,"x","")))-Returns!$G$13)/Returns!$B$8)^(1/Assumptions!$K$11)-1 -> 0.22511858 | G14: =((('Operating Model'!$G$5*G$11*VALUE(SUBSTITUTE($A14,"x","")))-Returns!$G$13)/Returns!$B$8)^(1/Assumptions!$K$11)-1 -> 0.24032354
A15: 13.0x | C15: =((('Operating Model'!$G$5*C$11*VALUE(SUBSTITUTE($A15,"x","")))-Returns!$G$13)/Returns!$B$8)^(1/Assumptions!$K$11)-1 -> 0.19510749 | D15: =((('Operating Model'!$G$5*D$11*VALUE(SUBSTITUTE($A15,"x","")))-Returns!$G$13)/Returns!$B$8)^(1/Assumptions!$K$11)-1 -> 0.21319855 | E15: =((('Operating Model'!$G$5*E$11*VALUE(SUBSTITUTE($A15,"x","")))-Returns!$G$13)/Returns!$B$8)^(1/Assumptions!$K$11)-1 -> 0.23027076 | F15: =((('Operating Model'!$G$5*F$11*VALUE(SUBSTITUTE($A15,"x","")))-Returns!$G$13)/Returns!$B$8)^(1/Assumptions!$K$11)-1 -> 0.24644478 | G15: =((('Operating Model'!$G$5*G$11*VALUE(SUBSTITUTE($A15,"x","")))-Returns!$G$13)/Returns!$B$8)^(1/Assumptions!$K$11)-1 -> 0.26182043
A16: 14.0x | C16: =((('Operating Model'!$G$5*C$11*VALUE(SUBSTITUTE($A16,"x","")))-Returns!$G$13)/Returns!$B$8)^(1/Assumptions!$K$11)-1 -> 0.21454628 | D16: =((('Operating Model'!$G$5*D$11*VALUE(SUBSTITUTE($A16,"x","")))-Returns!$G$13)/Returns!$B$8)^(1/Assumptions!$K$11)-1 -> 0.23281482 | E16: =((('Operating Model'!$G$5*E$11*VALUE(SUBSTITUTE($A16,"x","")))-Returns!$G$13)/Returns!$B$8)^(1/Assumptions!$K$11)-1 -> 0.2500606 | F16: =((('Operating Model'!$G$5*F$11*VALUE(SUBSTITUTE($A16,"x","")))-Returns!$G$13)/Returns!$B$8)^(1/Assumptions!$K$11)-1 -> 0.26640407 | G16: =((('Operating Model'!$G$5*G$11*VALUE(SUBSTITUTE($A16,"x","")))-Returns!$G$13)/Returns!$B$8)^(1/Assumptions!$K$11)-1 -> 0.28194498
A18: MOIC SENSITIVITY MATRIX
A19: Exit Multiple↓/ Margin → | C19: 0.28 | D19: 0.3 | E19: 0.32 | F19: 0.34 | G19: 0.36
A20: 10.0x | C20: =((('Operating Model'!$G$5*C$19*VALUE(SUBSTITUTE($A20,"x","")))-Returns!$G$13)/Returns!$B$8) -> 1.8235153 | D20: =((('Operating Model'!$G$5*D$19*VALUE(SUBSTITUTE($A20,"x","")))-Returns!$G$13)/Returns!$B$8) -> 1.9698227 | E20: =((('Operating Model'!$G$5*E$19*VALUE(SUBSTITUTE($A20,"x","")))-Returns!$G$13)/Returns!$B$8) -> 2.1161301 | F20: =((('Operating Model'!$G$5*F$19*VALUE(SUBSTITUTE($A20,"x","")))-Returns!$G$13)/Returns!$B$8) -> 2.2624375 | G20: =((('Operating Model'!$G$5*G$19*VALUE(SUBSTITUTE($A20,"x","")))-Returns!$G$13)/Returns!$B$8) -> 2.408745
A21: 11.0x | C21: =((('Operating Model'!$G$5*C$19*VALUE(SUBSTITUTE($A21,"x","")))-Returns!$G$13)/Returns!$B$8) -> 2.0283457 | D21: =((('Operating Model'!$G$5*D$19*VALUE(SUBSTITUTE($A21,"x","")))-Returns!$G$13)/Returns!$B$8) -> 2.1892838 | E21: =((('Operating Model'!$G$5*E$19*VALUE(SUBSTITUTE($A21,"x","")))-Returns!$G$13)/Returns!$B$8) -> 2.350222 | F21: =((('Operating Model'!$G$5*F$19*VALUE(SUBSTITUTE($A21,"x","")))-Returns!$G$13)/Returns!$B$8) -> 2.5111601 | G21: =((('Operating Model'!$G$5*G$19*VALUE(SUBSTITUTE($A21,"x","")))-Returns!$G$13)/Returns!$B$8) -> 2.6720983
A22: 12.0x | C22: =((('Operating Model'!$G$5*C$19*VALUE(SUBSTITUTE($A22,"x","")))-Returns!$G$13)/Returns!$B$8) -> 2.2331761 | D22: =((('Operating Model'!$G$5*D$19*VALUE(SUBSTITUTE($A22,"x","")))-Returns!$G$13)/Returns!$B$8) -> 2.408745 | E22: =((('Operating Model'!$G$5*E$19*VALUE(SUBSTITUTE($A22,"x","")))-Returns!$G$13)/Returns!$B$8) -> 2.5843139 | F22: =((('Operating Model'!$G$5*F$19*VALUE(SUBSTITUTE($A22,"x","")))-Returns!$G$13)/Returns!$B$8) -> 2.7598827 | G22: =((('Operating Model'!$G$5*G$19*VALUE(SUBSTITUTE($A22,"x","")))-Returns!$G$13)/Returns!$B$8) -> 2.9354516
A23: 13.0x | C23: =((('Operating Model'!$G$5*C$19*VALUE(SUBSTITUTE($A23,"x","")))-Returns!$G$13)/Returns!$B$8) -> 2.4380064 | D23: =((('Operating Model'!$G$5*D$19*VALUE(SUBSTITUTE($A23,"x","")))-Returns!$G$13)/Returns!$B$8) -> 2.6282061 | E23: =((('Operating Model'!$G$5*E$19*VALUE(SUBSTITUTE($A23,"x","")))-Returns!$G$13)/Returns!$B$8) -> 2.8184057 | F23: =((('Operating Model'!$G$5*F$19*VALUE(SUBSTITUTE($A23,"x","")))-Returns!$G$13)/Returns!$B$8) -> 3.0086054 | G23: =((('Operating Model'!$G$5*G$19*VALUE(SUBSTITUTE($A23,"x","")))-Returns!$G$13)/Returns!$B$8) -> 3.198805
A24: 14.0x | C24: =((('Operating Model'!$G$5*C$19*VALUE(SUBSTITUTE($A24,"x","")))-Returns!$G$13)/Returns!$B$8) -> 2.6428368 | D24: =((('Operating Model'!$G$5*D$19*VALUE(SUBSTITUTE($A24,"x","")))-Returns!$G$13)/Returns!$B$8) -> 2.8476672 | E24: =((('Operating Model'!$G$5*E$19*VALUE(SUBSTITUTE($A24,"x","")))-Returns!$G$13)/Returns!$B$8) -> 3.0524976 | F24: =((('Operating Model'!$G$5*F$19*VALUE(SUBSTITUTE($A24,"x","")))-Returns!$G$13)/Returns!$B$8) -> 3.257328 | G24: =((('Operating Model'!$G$5*G$19*VALUE(SUBSTITUTE($A24,"x","")))-Returns!$G$13)/Returns!$B$8) -> 3.4621583

Sheet Dashboard
A1: BLACKLINE TAKE -PRIVATE LBO – DASHBOARD
A3: TRANSACTION OVERVIEW
A4: ENTRY EV | B4: =Assumptions!C15 -> 2282.5334
A5: REVENUE | B5: =Assumptions!C10 -> 716.651
A6: EBITDA | B6: =Assumptions!C11 -> 185.146
A7: ENTRY MULTIPLE | B7: =Assumptions!C14 -> 12.328289
A9: CAPITAL STRUCTURE
A10: DEBT | B10: =Assumptions!C24 -> 925.73
A11: SPONSOR EQUITY | B11: ='Sources and Uses '!C12 -> 1445.9687
A12: DEBT% | B12: =B10/(B10+B11) -> 0.39032361
A13: EQUITY % | B13: =B11/(B10+B11) -> 0.60967639
A15: RETURNS SUMMARY
A16: EXIT EV | B16: =Returns!G12 -> 4172.9966
A17: EXIT EQUITY | B17: =Returns!G14 -> 3847.9594
A18: MOIC | B18: =Returns!G17 -> 2.6611637
A19: GROSS IRR | B19: =Returns!G18 -> 0.2162261
A21: INVESTMENT THESIS
A22: → Mission-critical financial close automation platform with recurring SaaS revenue profile
A23: →Margin expansion opportunity through operating leverage and go-to-market efficiency
A24: →Attractive sponsor entry valuation supported by public SaaS comps plus control premium
A26: KEY RISK
A27: →Revenue growth deceleration or weaker enterprise software demand
A28: →Execution risk around EBITDA margin expansion
A29: →Higher-for-longer interest rates reducing free cash flow and debt paydown capacity

Sheet PB_CACHE_JS
A1: {"Assumptions":{"F|^NAS:BLTotal Revenue Consensus MeanFY07/18/1905USD2026-07":{"id":56,"description":null,"headerValues":[{"simpleDate":null,"value":"PBXLP_UpgradeRequired","description":null}],"financialValues":[],"customValues":[],"error":null},"F|^58453-75Reported Total RevenueFY07/02/2026USDt":{"r":[[700427000]],"c":null,"a":["Assumptions!C10"]},"F|^58453-75Reported Total RevenueFY2026YUSD":{"id":60,"description":null,"headerValues":[],"financialValues":[],"customValues":[],"error":null},"F|^58453-75Total RevenueFY2026YUSD":{"id":61,"description":null,"headerValues":[],"financialValues":[],"customValues":[],"error":null},"F|^58453-75Total RevenueFY07/02/2026USDr":{"r":[[700427000]],"c":null,"a":["Assumptions!C10"]},"F|^58453-75EBITDAFY2026YUSD":{"id":63,"description":null,"headerValues":[],"financialValues":[],"customValues":[],"error":null},"F|^58453-75EBITDAFY07/02/2026USDr":{"r":[[72087000]],"c":null,"a":["Assumptions!C11"]},"F|^58453-75Total RevenueNTM07/02/2026USD":{"r":[[716651000]],"c":null,"a":["Assumptions!C10"]},"F|^58453-75EBITDANTM07/02/2026USD":{"r":[[75415000]],"c":null,"a":["Assumptions!C11"]},"F|^NAS:BLEBITDA (Normalized)NTM07/02/2026USD":{"r":[[185146000]],"c":null,"a":["Assumptions!C11"]},"M|^58453-75EV to Revenue07/02/202607/02/2026dasc0USD":{"id":70,"description":null,"headerValues":[],"financialValues":[],"customValues":[],"error":null},"F|^58453-75EV to RevenueNTM07/02/2026USD":{"r":[[2.6810609431927115]],"c":null,"a":["Assumptions!C13"]},"F|^58453-75EV to EBITDANTM07/02/2026USD":{"r":[[25.477491294835247]],"c":null,"a":["Assumptions!C14"]},"D|^58453-75Debt / EBITDAUSD":{"id":126,"description":null,"headerValues":[{"simpleDate":null,"value":"PBXLP_WRONG_INPUT","description":null}],"financialValues":[],"customValues":[],"error":null},"F|^58453-75Total Debt to EBITDANTM2026YUSD":{"id":127,"description":null,"headerValues":[],"financialValues":[],"customValues":[],"error":null},"F|^58453-75Total Debt to EBITDAFY2026YUSD":{"id":128,"description":null,"headerValues":[],"financialValues":[],"customValues":[],"error":null},"F|^58453-75Total Debt to EBITDAFY07/02/2026USDr":{"r":[[12.762986391443672]],"c":null,"a":["Assumptions!C23"]},"F|^58453-75Total Debt to EBITDANTM07/02/2026USD":{"r":[[11.591715176025989]],"c":null,"a":["Assumptions!C23"]}},"Sources":{"F|^NAS:BLEBITDA (Normalized)NTM07/02/2026USD":{"r":[[185146000]],"c":null,"a":["Sources!E4"]},"F|^NAS:BLEnterprise ValueNTM07/02/2026USD":{"r":[[1921385006]],"c":null,"a":["Sources!C4"]},"F|^NAS:BLRevenue GrowthNTM07/02/2026USD":{"r":[[0.08123794896244152]],"c":null,"a":["Sources!H4"]},"F|^NAS:BLTotal RevenueNTM07/02/2026USD":{"r":[[716651000]],"c":null,"a":["Sources!D4"]},"F|^NYS:BILLEBITDA (Normalized)NTM07/02/2026USD":{"r":[[289889000]],"c":null,"a":["Sources!E5"]},"F|^NYS:BILLEnterprise ValueNTM07/02/2026USD":{"r":[[3574870073]],"c":null,"a":["Sources!C5"]},"F|^NYS:BILLRevenue GrowthNTM07/02/2026USD":{"r":[[0.12470298021273685]],"c":null,"a":["Sources!H5"]},"F|^NYS:BILLTotal RevenueNTM07/02/2026USD":{"r":[[1600323000]],"c":null,"a":["Sources!D5"]},"F|^NAS:SPTEBITDA (Normalized)NTM07/02/2026USD":{"r":[[51991000]],"c":null,"a":["Sources!E7"]},"F|^NAS:SPTEnterprise ValueNTM07/02/2026USD":{"r":[[415178248]],"c":null,"a":["Sources!C7"]},"F|^NAS:SPTRevenue GrowthNTM07/02/2026USD":{"r":[[0.1227065124649569]],"c":null,"a":["Sources!H7"]},"F|^NAS:SPTTotal RevenueNTM07/02/2026USD":{"r":[[469755000]],"c":null,"a":["Sources!D7"]},"F|^NYS:QTWOEBITDA (Normalized)NTM07/02/2026USD":{"r":[[205836000]],"c":null,"a":["Sources!E8"]},"F|^NYS:QTWOEnterprise ValueNTM07/02/2026USD":{"r":[[3107552235]],"c":null,"a":["Sources!C8"]},"F|^NYS:QTWORevenue GrowthNTM07/02/2026USD":{"r":[[0.139989260307122]],"c":null,"a":["Sources!H8"]},"F|^NYS:QTWOTotal RevenueNTM07/02/2026USD":{"r":[[821580000]],"c":null,"a":["Sources!D8"]},"F|^NAS:FRSHEBITDA (Normalized)NTM07/02/2026USD":{"r":[[176622000]],"c":null,"a":["Sources!E6"]},"F|^NAS:FRSHEnterprise ValueNTM07/02/2026USD":{"r":[[2137237679]],"c":null,"a":["Sources!C6"]},"F|^NAS:FRSHRevenue GrowthNTM07/02/2026USD":{"r":[[0.15916306300312688]],"c":null,"a":["Sources!H6"]},"F|^NAS:FRSHTotal RevenueNTM07/02/2026USD":{"r":[[871169000]],"c":null,"a":["Sources!D6"]},"F|^NAS:BLEnterprise Value07/02/2026USD":{"r":[[1921385006]],"c":null,"a":["Sources!C4"]},"F|^NYS:BILLEnterprise Value07/02/2026USD":{"r":[[3574870073]],"c":null,"a":["Sources!C5"]},"F|^NAS:SPTEnterprise Value07/02/2026USD":{"r":[[415178248]],"c":null,"a":["Sources!C7"]},"F|^NYS:QTWOEnterprise Value07/02/2026USD":{"r":[[3107552235]],"c":null,"a":["Sources!C8"]},"F|^NAS:FRSHEnterprise Value07/02/2026USD":{"r":[[2137237679]],"c":null,"a":["Sources!C6"]},"MATCHSYMBOL|^BlackLine ":{"r":[["NAS:BL"]]},"MATCHSYMBOL|^BILL Holdings":{"r":[["NYS:BILL"]]},"MATCHSYMBOL|^Q2 Holdings":{"r":[["NYS:QTWO"]]},"MATCHSYMBOL|^Freshworks":{"r":[["NAS:FRSH"]]},"MATCHSYMBOL|^Sprout Social":{"r":[["NAS:SPT"]]}}}

Sheet CACHE_CHARTS_JS
