Workbook

Sheet Deal Fact Sheet
A1: SpaceX IPO Deal Fact Sheet
A3: Item | B3: Entity/PBID | C3: Value | D3: Units | E3: Source | F3: Confidence | G3: Notes
A4: IPO TRANSACTION TERMS
A5: Company | B5: 46488-07 | C5: SpaceX | D5: Text | E5: Prospectus/S-1 | F5: H | G5: issuer
A6: Ticker | B6: 46488-07 | C6: SPCX | D6: Text | E6: Prospectus/Nasdaq | F6: H | G6: Public ticker
A7: Exchange | B7: 46488-07 | C7: Nasdaq | D7: Text | E7: Prospectus/Nasdaq | F7: H | G7: Verify exact listing venue
A8: IPO Pricing date | B8: 46488-07 | C8: 46184 | D8: Date | E8: 424B4/price release | F8: H | G8: Pricing Night
A9: First Trading date | B9: 46488-07 | C9: 46185 | D9: Date | E9: Nasdaq/market data | F9: H | G9: First Trading Session
A10: Offer Price | B10: 46488-07 | C10: 135 | D10: $/Share | E10: 424B4/price release | F10: H | G10: Hardcoded Input
A11: Shares Offered | B11: 46488-07 | C11: 555.556 | D11: mm shares | E11: 424B4/price release | F11: H | G11: Shares Sold In IPO
A12: Gross Proceeds | B12: 46488-07 | C12: =C10*C11 -> 75000.06 | D12: $mm | E12: formula | F12: H | G12: Offer price x Shares Offered
A13: Greenshoe Shares | B13: 46488-07 | C13: 83.33 | D13: mm shares | E13: 424B4/price release | F13: H/M | G13: Overallotment shares, exercised in full
A14: Total Proceed Incl. Greenshoe | B14: 46488-07 | C14: =C12+(C13*C10) -> 86249.61 | D14: $mm | E14: Formula | F14: H/M | G14: only valid after greenshoe is filled
A15: Primary/Secondary Mix | B15: 46488-07 | C15: 100% primary | D15: %/$mm | E15: Prospectus | F15: H | G15: need exact split
A16: Lead Underwriters | B16: 46488-07 | C16: Goldman Sachs/Morgan Stanley /BofA/Citigroup/J.P. Morgan | D16: Text | E16: Prospectus | F16: H | G16: Verify From final prospectus
A18: BUSINESS ENGINES
A19: Starlink/Connectivity | B19: 46488-07 | C19: Recurring satellite broadband business serving consumer, enterprise, aviation, maritime, direct-to-cell, and government connectivity customers | D19: Text | E19: S-1 business section | F19: H | G19: High-growth recurring revenue; premium multiple candidate
A20: Launch Services | B20: 46488-07 | C20: Launch business using Falcon 9, Falcon Heavy, and Starship for commercial, civil government, NASA, national security, and other payload missions | D20: Text | E20: S-1 business section | F20: H | G20: Cadence / contract-driven valuation lens
A21: Starshield /Defense/Other | B21: 46488-07 | C21: Secure satellite communications and defense/government programs, if separately disclosed | D21: Text | E21: S-1 business section | F21: M | G21: Keep separate only if disclosure supports it
A22: Valuation Implications | B22: 46488-07 | C22: Starlink and Launch should be valued separately because recurring connectivity revenue and launch services have different growth, margin, capex, and multiple profiles | D22: Text | E22: Model Judgment | F22: M | G22: Justifies SOTP later
A24: FINANCIAL PROFILE
A25: FY Revenue | B25: 46488-07 | C25: {=_xll.PBF(B25,"Total Revenue","FY","2025Y","","USD","")/1000000} -> 18674 | D25: $mm | E25: S-1 / 424B4 | F25: H | G25: Latest fiscal year
A26: Revenue Growth | B26: 46488-07 | C26: {=_xll.PBF(B25,"Revenue % Growth","FY","2025Y","","USD","")} -> 0.33242954 | D26: % | E26: S-1 / 424B4 | F26: H | G26: YoY growth
A27: Q1 Revenue | B27: 46488-07 | C27: {=_xll.PBF(B25,"Total Revenue","FQ","2026Q1","","USD","")/1000000} -> 4694 | D27: $mm | E27: S-1 / 424B4 | F27: H | G27: Latest quarter
A28: Q1 Revenue Growth | B28: 46488-07 | C28: {=_xll.PBF(B25,"Revenue % Growth","FQ","2026Q1","","USD","")} -> 0.15416769 | D28: % | E28: S-1 / 424B4 | F28: H | G28: YoY growth
A29: EBITDA/ Adj. EBITDA | B29: 46488-07 | C29: {=_xll.PBF(B29,"EBITDA (Normalized)","FY","2025Y","","USD","")/1000000} -> 6584 | D29: $mm | E29: S-1 / 424B4 | F29: H/M | G29: Use exact disclosed metric
A30: Loss from operations | B30: 46488-07 | C30: -2589 | D30: $mm | E30: S-1 / 424B4 | F30: H | G30: Negative shown in parentheses
A31: Capex | B31: 46488-07 | C31: 20737 | D31: $mm | E31: S-1 / 424B4 | F31: H | G31: Important for DCF / FCF
A32: Cash and Equivalents | B32: 46488-07 | C32: {=_xll.PBF(B32,"Cash and Cash Equivalents","TTM","24-Jun-2026","","USD","t")/1000000} -> 15852 | D32: $mm | E32: S-1 / 424B4 | F32: H | G32: Needed for EV
A33: Debt | B33: 46488-07 | C33: 29111 | D33: $mm | E33: S-1 / 424B4 | F33: H | G33: Needed for EV
A34: Starlink/Connectivity Revenue | B34: 46488-07 | C34: 11387 | D34: $mm | E34: S-1 / Estimate | F34: H/M/L | G34: H only if disclosed
A35: Space / Launch Revenue | B35: 46488-07 | C35: 4086 | D35: $mm | E35: S-1 / Estimate | F35: H/M/L | G35: H only if disclosed
A36: AI / xAI Revenue | B36: 46488-07 | C36: 3201 | D36: $mm | E36: 424B4 | F36: H | G36: FY2025 AI segment revenue
A37: Connectivity Segment Adj. EBITDA | B37: 46488-07 | C37: 7168 | D37: $mm | E37: S-1 / 424B4 | F37: H/M | G37: If disclosed
A38: AI / xAI Segment Adj. EBITDA | B38: 46488-07 | C38: -1237 | D38: $mm | E38: 424B4 | F38: H | G38: FY2025 AI segment adjusted EBITDA
A39: Segment Disclosure Caveat | B39: 46488-07 | C39: FY2025 segment revenue reconciles to total company revenue: Connectivity $11,387mm + Space $4,086mm + AI $3,201mm = total FY2025 revenue of $18,674mm. Segment adjusted EBITDA is disclosed for Connectivity and AI; Space EBITDA should remain N/D unless separately disclosed. | D39: Text | E39: Model Judgment | F39: M | G39: Explain which segment figures are estimated
A45: VALUATION SNAPSHOT
A46: TOTAL DILUTED SHARES OUTSTANDING | B46: 46488-07 | C46: 13159.199 | D46: mm shares | E46: 424B4/Prospectus | F46: H | G46: Do not confuse with shares offered
A47: IPO EQUITY VALUE | B47: 46488-07 | C47: =C10*C46 -> 1776491.8 | D47: $mm | E47: Formula | F47: H | G47: offer price x Shares offered
A48: CASH AND EQUIVALENTS | B48: 46488-07 | C48: {=_xll.PBF(B48,"Cash and Cash Equivalents","TTM","24-Jun-2026","","USD","t")/1000000} -> 15852 | D48: $mm | E48: link to row 32 | F48: H | G48: internal link
...

Sheet Valuation Bridge 
A1: SpaceX Valuation Bridge
A3: Item | B3: Reference | C3: Value | D3: Units | E3: Source | F3: Confidence | G3: Notes
A4: PRIVATE-TO-IPO VALUATION BRIDGE
A5: Last Private Post Money Valuation | B5: Deal Fact Sheet!C60 | C5: ='Deal Fact Sheet'!C68 -> 350000 | D5: $mm | E5: PitchBook | F5: M/H | G5: Last private valuation before IPO; verify round date and valuation source
A6: IPO Equity Value | B6: Deal Fact Sheet!C41 | C6: ='Deal Fact Sheet'!C47 -> 1776491.8 | D6: $mm | E6: Formula | F6: H | G6: Offer price × diluted shares
A7: Day-1 Equity Value | B7: Deal Fact Sheet!C48 | C7: ='Deal Fact Sheet'!C55 -> 2117973 | D7: $mm | E7: Formula | F7: H | G7: Day-1 close × diluted shares
A8: IPO Uplift vs Last Private Valuation | B8: Model | C8: =IFERROR((C6/C5)-1,"") -> 4.0756909 | D8: % | E8: Formula | F8: M/H | G8: Private-to-IPO re-rating
A9: Day-1 Uplift vs Last Private Valuation | B9: Model | C9: =IFERROR((C7/C5)-1,"") -> 5.0513514 | D9: % | E9: Formula | F9: M/H | G9: Private-to-Day-1 re-rating
A10: Day-1 Uplift vs IPO Equity Value | B10: Model | C10: =IFERROR((C7/C6)-1,"") -> 0.19222222 | D10: % | E10: Formula | F10: H | G10: Same as Day-1 pop if share count constant
A11: Equity value Created From IPO to Day-1 | B11: Model | C11: =C7-C6 -> 341481.2 | D11: $mm | E11: Formula | F11: H | G11: Public market uplift after pricing
A12: Money left on the table | B12: Deal Fact Sheet!C51 | C12: ='Deal Fact Sheet'!C58 -> 14416.678 | D12: $mm | E12: Formula | F12: H | G12: Offer-to-Day-1 spread × shares offered
A13: Bridge Conclusion | B13: Model | C13: SpaceX’s IPO equity value represented a 408% uplift versus its last private valuation, while the Day-1 close implied a 505% uplift versus the last private valuation and a 19.2% uplift versus IPO pricing. The IPO-to-Day-1 move created approximately $341.5bn of incremental public market equity value, while the offer-to-close spread implied approximately $14.4bn of value left on the table. | D13: Text | E13: Model Judgement | F13: M

Sheet Aftermarket Trading 
A1: SpaceX Aftermarket Trading
A3: Date | B3: Trading Day | C3: Close Price | D3: % vs IPO Price | E3: Volume | F3: Equity Value | G3: Enterprise value | H3: Notes
A4: First Week Trading Perfomance
A5: 46185 | B5: Day 1 | C5: {=_xll.PBM("46488-07","Close Price",TEXT(A5,"dd-mmm-yyyy"),TEXT(A5,"dd-mmm-yyyy"),"0","d","asc","USD","")} -> 160.95 | D5: =C5/'Deal Fact Sheet'!$C$10-1 -> 0.19222222 | E5: 522132000 | F5: =C5*'Deal Fact Sheet'!$C$46 -> 2117973 | G5: =F5+'Deal Fact Sheet'!C50-'Deal Fact Sheet'!C48 -> 2131232 | H5: First trading close
A6: 46188 | B6: Day 2 | C6: {=_xll.PBM("46488-07","Close Price",A6,A6,"0","d","asc","USD","")} -> 192.5 | D6: =C6/'Deal Fact Sheet'!$C$10-1 -> 0.42592593 | E6: 256226632 | F6: =C6*'Deal Fact Sheet'!$C$46 -> 2533145.7 | G6: =IF(F6="","",F6+'Deal Fact Sheet'!$C$50-'Deal Fact Sheet'!$C$48) -> 2546404.7
A7: 46189 | B7: Day 3 | C7: {=_xll.PBM("46488-07","Close Price",A7,A7,"0","d","asc","USD","")} -> 201.8 | D7: =C7/'Deal Fact Sheet'!$C$10-1 -> 0.49481481 | E7: 322149250 | F7: =C7*'Deal Fact Sheet'!$C$46 -> 2655526.3 | G7: =IF(F7="","",F7+'Deal Fact Sheet'!$C$50-'Deal Fact Sheet'!$C$48) -> 2668785.3
A8: 46190 | B8: Day 4 | C8: {=_xll.PBM("46488-07","Close Price",A8,A8,"0","d","asc","USD","")} -> 191.82 | D8: =C8/'Deal Fact Sheet'!$C$10-1 -> 0.42088889 | E8: 201719498 | F8: =C8*'Deal Fact Sheet'!$C$46 -> 2524197.5 | G8: =IF(F8="","",F8+'Deal Fact Sheet'!$C$50-'Deal Fact Sheet'!$C$48) -> 2537456.5
A9: 46191 | B9: Day 5 | C9: {=_xll.PBM("46488-07","Close Price",A9,A9,"0","d","asc","USD","")} -> 185 | D9: =C9/'Deal Fact Sheet'!$C$10-1 -> 0.37037037 | E9: 271421211 | F9: =C9*'Deal Fact Sheet'!$C$46 -> 2434451.7 | G9: =IF(F9="","",F9+'Deal Fact Sheet'!$C$50-'Deal Fact Sheet'!$C$48) -> 2447710.7
A10: 46192 | B10: Day 6 | C10: {=_xll.PBM("46488-07","Close Price",A10,A10,"0","d","asc","USD","")} -> 185 | D10: =C10/'Deal Fact Sheet'!$C$10-1 -> 0.37037037 | E10: N/A - market closed | F10: =C10*'Deal Fact Sheet'!$C$46 -> 2434451.7 | G10: =IF(F10="","",F10+'Deal Fact Sheet'!$C$50-'Deal Fact Sheet'!$C$48) -> 2447710.7 | H10: Juneteenth market holiday; no regular trading volume
A11: 46195 | B11: Day 7 | C11: {=_xll.PBM("46488-07","Close Price",A11,A11,"0","d","asc","USD","")} -> 154.6 | D11: =C11/'Deal Fact Sheet'!$C$10-1 -> 0.14518519 | E11: 163833848 | F11: =C11*'Deal Fact Sheet'!$C$46 -> 2034412.1 | G11: =IF(F11="","",F11+'Deal Fact Sheet'!$C$50-'Deal Fact Sheet'!$C$48) -> 2047671.1
A12: 46196 | B12: Day 8 | C12: {=_xll.PBM("46488-07","Close Price",A12,A12,"0","d","asc","USD","")} -> 156.11 | D12: =C12/'Deal Fact Sheet'!$C$10-1 -> 0.15637037 | E12: 155848109 | F12: =C12*'Deal Fact Sheet'!$C$46 -> 2054282.5 | G12: =IF(F12="","",F12+'Deal Fact Sheet'!$C$50-'Deal Fact Sheet'!$C$48) -> 2067541.5
A13: 46197 | B13: Day 9 | C13: {=_xll.PBM("46488-07","Close Price",A13,A13,"0","d","asc","USD","")} -> 154.54 | D13: =C13/'Deal Fact Sheet'!$C$10-1 -> 0.14474074 | E13: 76101541 | F13: =C13*'Deal Fact Sheet'!$C$46 -> 2033622.5 | G13: =IF(F13="","",F13+'Deal Fact Sheet'!$C$50-'Deal Fact Sheet'!$C$48) -> 2046881.5
A14: 46198 | B14: Day 10 | C14: {=_xll.PBM("46488-07","Close Price",A14,A14,"0","d","asc","USD","")} -> 153 | D14: =C14/'Deal Fact Sheet'!$C$10-1 -> 0.13333333 | E14: 62025308 | F14: =C14*'Deal Fact Sheet'!$C$46 -> 2013357.4 | G14: =IF(F14="","",F14+'Deal Fact Sheet'!$C$50-'Deal Fact Sheet'!$C$48) -> 2026616.4
A15: 46199 | B15: Day 11 | C15: {=_xll.PBM("46488-07","Close Price",A15,A15,"0","d","asc","USD","")} -> 153.23 | D15: =C15/'Deal Fact Sheet'!$C$10-1 -> 0.13503704 | E15: 125300711 | F15: =C15*'Deal Fact Sheet'!$C$46 -> 2016384 | G15: =IF(F15="","",F15+'Deal Fact Sheet'!$C$50-'Deal Fact Sheet'!$C$48) -> 2029643 | H15: Latest available trading close / volume
A19: Day -1 POP | C19: =D5 -> 0.19222222
A20: Latest %vs IPO | C20: =D15 -> 0.13503704
A21: Equity Value Created from IPO on Day 1 | C21: =F5-'Deal Fact Sheet'!C47 -> 341481.2
A23: Aftermarket Conclusion
A24: SpaceX traded up meaningfully on Day 1, closing at $160.95 versus the $135.00 IPO price, implying a 19.2% first-day pop and approximately $341.5bn of equity value creation versus the IPO pricing valuation. The stock remained above the IPO price through the observed aftermarket period, supporting the view that the IPO was priced below early public-market demand, although subsequent volatility indicates the market was still recalibrating around SpaceX’s long-term growth, capex intensity, and segment valuation assumptions.

Sheet Trading Comps
A1: SpaceX Trading Comparables
A3: Segment | B3: Company | C3: Ticker | D3: Market Cap | E3: Enterprise Value | F3: Revenue | G3: EBITDA | H3: EBITDA Margin | I3: EV/Revenue | J3: EV/EBITDA | K3: Revenue Growth | L3: Source | M3: Confidence | N3: Notes
A4: STARLINK/CONNECTIVITY COMPS
A5: Connectivity | B5: Viasat | C5: VSAT | D5: {=_xll.PBM(C5,"Market Cap","23-Jun-2026","23-Jun-2026","0","d","asc","USD","/1000000")} -> 8771.8239 | E5: {=_xll.PBF(C5,"EV","TTM","23-Jun-2026","","USD","t")/1000000} -> 11720.076 | F5: {=_xll.PBF(C5,"Total Revenue","TTM","23-Jun-2026","","USD","t")/1000000} -> 4640.28 | G5: {=_xll.PBF(C5,"EBITDA","TTM","23-Jun-2026","","USD","t")/1000000} -> 1613.667 | H5: =IFERROR(G5/F5,"") -> 0.34775208 | I5: =IFERROR(E5/F5,"") -> 2.5257261 | J5: =IFERROR(E5/G5,"") -> 7.2630079 | K5: {=_xll.PBF(C5,"Revenue % Growth","TTM","23-Jun-2026","","USD","t")} -> 0.026708066 | L5: PitchBook
A6: Connectivity | B6: Echostar | C6: SATS | D6: {=_xll.PBM(C6,"Market Cap","23-Jun-2026","23-Jun-2026","0","d","asc","USD","/1000000")} -> 30836.155 | E6: {=_xll.PBF(C6,"EV","TTM","23-Jun-2026","","USD","t")/1000000} -> 60998.086 | F6: {=_xll.PBF(C6,"Total Revenue","TTM","23-Jun-2026","","USD","t")/1000000} -> 14802.72 | G6: {=_xll.PBF(C6,"EBITDA","TTM","23-Jun-2026","","USD","t")/1000000} -> -15894.744 | H6: =IFERROR(G6/F6,"") -> -1.0737718 | I6: =IFERROR(E6/F6,"") -> 4.120735 | J6: N/M | K6: {=_xll.PBF(C6,"Revenue % Growth","TTM","23-Jun-2026","","USD","t")} -> -0.055974928 | L6: PitchBook
A7: Connectivity | B7: Iridium | C7: IRDM | D7: {=_xll.PBM(C7,"Market Cap","23-Jun-2026","23-Jun-2026","0","d","asc","USD","/1000000")} -> 4578.0113 | E7: {=_xll.PBF(C7,"EV","TTM","23-Jun-2026","","USD","t")/1000000} -> 4575.5255 | F7: {=_xll.PBF(C7,"Total Revenue","TTM","23-Jun-2026","","USD","t")/1000000} -> 875.838 | G7: {=_xll.PBF(C7,"EBITDA","TTM","23-Jun-2026","","USD","t")/1000000} -> 437.162 | H7: =IFERROR(G7/F7,"") -> 0.49913568 | I7: =IFERROR(E7/F7,"") -> 5.2241687 | J7: =IFERROR(E7/G7,"") -> 10.46643 | K7: {=_xll.PBF(C7,"Revenue % Growth","TTM","23-Jun-2026","","USD","t")} -> 0.04054974 | L7: PitchBook
A8: Connectivity | B8: Globalstar | C8: GSAT | D8: {=_xll.PBM(C8,"Market Cap","23-Jun-2026","23-Jun-2026","0","d","asc","USD","/1000000")} -> 10278.645 | E8: {=_xll.PBF(C8,"EV","TTM","23-Jun-2026","","USD","t")/1000000} -> 8637.4438 | F8: {=_xll.PBF(C8,"Total Revenue","TTM","23-Jun-2026","","USD","t")/1000000} -> 283.018 | G8: {=_xll.PBF(C8,"EBITDA","TTM","23-Jun-2026","","USD","t")/1000000} -> 130.467 | H8: =IFERROR(G8/F8,"") -> 0.46098481 | I8: =IFERROR(E8/F8,"") -> 30.519062 | J8: =IFERROR(E8/G8,"") -> 66.20405 | K8: {=_xll.PBF(C8,"Revenue % Growth","TTM","23-Jun-2026","","USD","t")} -> 0.11467856 | L8: PitchBook
A9: Connectivity | B9: AST SpaceMobile | C9: ASTS | D9: {=_xll.PBM(C9,"Market Cap","23-Jun-2026","23-Jun-2026","0","d","asc","USD","/1000000")} -> 21865.248 | E9: {=_xll.PBF(C9,"EV","TTM","23-Jun-2026","","USD","t")/1000000} -> 24705.508 | F9: {=_xll.PBF(C9,"Total Revenue","TTM","23-Jun-2026","","USD","t")/1000000} -> 84.935 | G9: {=_xll.PBF(C9,"EBITDA","TTM","23-Jun-2026","","USD","t")/1000000} -> -596.719 | H9: =IFERROR(G9/F9,"") -> -7.025596 | I9: =IFERROR(E9/F9,"") -> 290.87547 | J9: N/M | K9: {=_xll.PBF(C9,"Revenue % Growth","TTM","23-Jun-2026","","USD","t")} -> 17.320751 | L9: PitchBook | N9: Extreme direct-to-cell satellite growth outlier; exclude from median
A10: Connectivity | B10: T-Mobile | C10: TMUS | D10: {=_xll.PBM(C10,"Market Cap","23-Jun-2026","23-Jun-2026","0","d","asc","USD","/1000000")} -> 194861.78 | E10: {=_xll.PBF(C10,"EV","TTM","23-Jun-2026","","USD","t")/1000000} -> 348095.23 | F10: {=_xll.PBF(C10,"Total Revenue","TTM","23-Jun-2026","","USD","t")/1000000} -> 90530 | G10: {=_xll.PBF(C10,"EBITDA","TTM","23-Jun-2026","","USD","t")/1000000} -> 31793 | H10: =IFERROR(G10/F10,"") -> 0.35118745 | I10: =IFERROR(E10/F10,"") -> 3.8450815 | J10: =IFERROR(E10/G10,"") -> 10.948801 | K10: {=_xll.PBF(C10,"Revenue % Growth","TTM","23-Jun-2026","","USD","t")} -> 0.094785469 | L10: PitchBook
A11: Connectivity | B11: Charter | C11: CHTR | D11: {=_xll.PBM(C11,"Market Cap","23-Jun-2026","23-Jun-2026","0","d","asc","USD","/1000000")} -> 15439.479 | E11: {=_xll.PBF(C11,"EV","TTM","23-Jun-2026","","USD","t")/1000000} -> 128238.01 | F11: {=_xll.PBF(C11,"Total Revenue","TTM","23-Jun-2026","","USD","t")/1000000} -> 54636 | G11: {=_xll.PBF(C11,"EBITDA","TTM","23-Jun-2026","","USD","t")/1000000} -> 21230 | H11: =IFERROR(G11/F11,"") -> 0.38857164 | I11: =IFERROR(E11/F11,"") -> 2.347134 | J11: =IFERROR(E11/G11,"") -> 6.040415 | K11: {=_xll.PBF(C11,"Revenue % Growth","TTM","23-Jun-2026","","USD","t")} -> -0.0091583395 | L11: PitchBook
A13: LAUNCH/SPACE INFRASTRUCTURE COMPS
A14: SPACE | B14: Rocket Lab | C14: RKLB | D14: {=_xll.PBM(C14,"Market Cap","23-Jun-2026","23-Jun-2026","0","d","asc","USD","/1000000")} -> 62663.07 | E14: {=_xll.PBF(C14,"EV","TTM","23-Jun-2026","","USD","t")/1000000} -> 35804.743 | F14: {=_xll.PBF(C14,"Total Revenue","TTM","23-Jun-2026","","USD","t")/1000000} -> 679.578 | G14: {=_xll.PBF(C14,"EBITDA","TTM","23-Jun-2026","","USD","t")/1000000} -> -171.548 | H14: =IFERROR(G14/F14,"") -> -0.25243313 | I14: =IFERROR(E14/F14,"") -> 52.686731 | J14: N/M | K14: {=_xll.PBF(C14,"Revenue % Growth","TTM","23-Jun-2026","","USD","t")} -> 0.45827182 | L14: PitchBook
A15: SPACE | B15: Planet Labs | C15: PL | D15: {=_xll.PBM(C15,"Market Cap","23-Jun-2026","23-Jun-2026","0","d","asc","USD","/1000000")} -> 10253.701 | E15: {=_xll.PBF(C15,"EV","TTM","23-Jun-2026","","USD","t")/1000000} -> 12432.488 | F15: {=_xll.PBF(C15,"Total Revenue","TTM","23-Jun-2026","","USD","t")/1000000} -> 335.612 | G15: {=_xll.PBF(C15,"EBITDA","TTM","23-Jun-2026","","USD","t")/1000000} -> -339.975 | H15: =IFERROR(G15/F15,"") -> -1.0130001 | I15: =IFERROR(E15/F15,"") -> 37.04423 | J15: N/M | K15: {=_xll.PBF(C15,"Revenue % Growth","TTM","23-Jun-2026","","USD","t")} -> 0.34149822 | L15: PitchBook
A16: SPACE | B16: Redwire | C16: RDW | D16: {=_xll.PBM(C16,"Market Cap","23-Jun-2026","23-Jun-2026","0","d","asc","USD","/1000000")} -> 3109.506 | E16: {=_xll.PBF(C16,"EV","TTM","23-Jun-2026","","USD","t")/1000000} -> 1737.4443 | F16: {=_xll.PBF(C16,"Total Revenue","TTM","23-Jun-2026","","USD","t")/1000000} -> 370.958 | G16: {=_xll.PBF(C16,"EBITDA","TTM","23-Jun-2026","","USD","t")/1000000} -> -244.877 | H16: =IFERROR(G16/F16,"") -> -0.66012055 | I16: =IFERROR(E16/F16,"") -> 4.6836686 | J16: N/M | K16: {=_xll.PBF(C16,"Revenue % Growth","TTM","23-Jun-2026","","USD","t")} -> 0.33580359 | L16: PitchBook
A17: SPACE | B17: Intuitive Machines | C17: LUNR | D17: {=_xll.PBM(C17,"Market Cap","23-Jun-2026","23-Jun-2026","0","d","asc","USD","/1000000")} -> 3528.3463 | E17: {=_xll.PBF(C17,"EV","TTM","23-Jun-2026","","USD","t")/1000000} -> 3706.1738 | F17: {=_xll.PBF(C17,"Total Revenue","TTM","23-Jun-2026","","USD","t")/1000000} -> 328.238 | G17: {=_xll.PBF(C17,"EBITDA","TTM","23-Jun-2026","","USD","t")/1000000} -> -146.611 | H17: =IFERROR(G17/F17,"") -> -0.44666065 | I17: =IFERROR(E17/F17,"") -> 11.291118 | J17: N/M | K17: {=_xll.PBF(C17,"Revenue % Growth","TTM","23-Jun-2026","","USD","t")} -> 0.51049447 | L17: PitchBook
A18: SPACE | B18: BlackSky | C18: BKSY | D18: {=_xll.PBM(C18,"Market Cap","23-Jun-2026","23-Jun-2026","0","d","asc","USD","/1000000")} -> 1059.0916 | E18: {=_xll.PBF(C18,"EV","TTM","23-Jun-2026","","USD","t")/1000000} -> 1015.8035 | F18: {=_xll.PBF(C18,"Total Revenue","TTM","23-Jun-2026","","USD","t")/1000000} -> 97.805 | G18: {=_xll.PBF(C18,"EBITDA","TTM","23-Jun-2026","","USD","t")/1000000} -> -42.77 | H18: =IFERROR(G18/F18,"") -> -0.43729871 | I18: =IFERROR(E18/F18,"") -> 10.386008 | J18: N/M | K18: {=_xll.PBF(C18,"Revenue % Growth","TTM","23-Jun-2026","","USD","t")} -> -0.089347399 | L18: PitchBook
A19: SPACE | B19: MDA Space | C19: MDA | D19: {=_xll.PBM(C19,"Market Cap","23-Jun-2026","23-Jun-2026","0","d","asc","USD","/1000000")} -> 5483.1683 | E19: {=_xll.PBF(C19,"EV","TTM","23-Jun-2026","","USD","t")/1000000} -> 3673.9361 | F19: {=_xll.PBF(C19,"Total Revenue","TTM","23-Jun-2026","","USD","t")/1000000} -> 1263.311 | G19: {=_xll.PBF(C19,"EBITDA","TTM","23-Jun-2026","","USD","t")/1000000} -> 232.36298 | H19: =IFERROR(G19/F19,"") -> 0.18393174 | I19: =IFERROR(E19/F19,"") -> 2.9081803 | J19: =IFERROR(E19/G19,"") -> 15.811193 | K19: {=_xll.PBF(C19,"Revenue % Growth","TTM","23-Jun-2026","","USD","t")} -> 0.42905074 | L19: PitchBook
A20: SPACE | B20: Sidus Space | C20: SIDU | D20: {=_xll.PBM(C20,"Market Cap","23-Jun-2026","23-Jun-2026","0","d","asc","USD","/1000000")} -> 301.78467 | E20: {=_xll.PBF(C20,"EV","TTM","23-Jun-2026","","USD","t")/1000000} -> 151.56936 | F20: {=_xll.PBF(C20,"Total Revenue","TTM","23-Jun-2026","","USD","t")/1000000} -> 3.504756 | G20: {=_xll.PBF(C20,"EBITDA","TTM","23-Jun-2026","","USD","t")/1000000} -> -24.40707 | H20: =IFERROR(G20/F20,"") -> -6.9639855 | I20: =IFERROR(E20/F20,"") -> 43.246766 | J20: N/M | K20: {=_xll.PBF(C20,"Revenue % Growth","TTM","23-Jun-2026","","USD","t")} -> -0.092263762 | L20: PitchBook | N20: Very small-cap space infrastructure comp; use as reference / high-risk comp
A22: AEROSPACE & DEFENSE / STRATEGIC ASSET COMPS
A23: Aerospace | B23: Lockheed Martin | C23: LMT | D23: {=_xll.PBM(C23,"Market Cap","23-Jun-2026","23-Jun-2026","0","d","asc","USD","/1000000")} -> 113806.2 | E23: {=_xll.PBF(C23,"EV","TTM","23-Jun-2026","","USD","t")/1000000} -> 156868 | F23: {=_xll.PBF(C23,"Total Revenue","TTM","23-Jun-2026","","USD","t")/1000000} -> 75106 | G23: {=_xll.PBF(C23,"EBITDA","TTM","23-Jun-2026","","USD","t")/1000000} -> 8467 | H23: =IFERROR(G23/F23,"") -> 0.112734 | I23: =IFERROR(E23/F23,"") -> 2.0886214 | J23: =IFERROR(E23/G23,"") -> 18.526987 | K23: {=_xll.PBF(C23,"Revenue % Growth","TTM","23-Jun-2026","","USD","t")} -> 0.045884335 | L23: PitchBook
A24: Aerospace | B24: Boeing | C24: BA | D24: {=_xll.PBM(C24,"Market Cap","23-Jun-2026","23-Jun-2026","0","d","asc","USD","/1000000")} -> 174080.8 | E24: {=_xll.PBF(C24,"EV","TTM","23-Jun-2026","","USD","t")/1000000} -> 181448.56 | F24: {=_xll.PBF(C24,"Total Revenue","TTM","23-Jun-2026","","USD","t")/1000000} -> 92184 | G24: {=_xll.PBF(C24,"EBITDA","TTM","23-Jun-2026","","USD","t")/1000000} -> 7324 | H24: =IFERROR(G24/F24,"") -> 0.079449796 | I24: =IFERROR(E24/F24,"") -> 1.9683303 | J24: =IFERROR(E24/G24,"") -> 24.774517 | K24: {=_xll.PBF(C24,"Revenue % Growth","TTM","23-Jun-2026","","USD","t")} -> 0.3274581 | L24: PitchBook | N24: Broad aerospace / defense company with space exposure; reference comp, not a pure launch comp.
A25: Aerospace | B25: Northrop Grumman | C25: NOC | D25: {=_xll.PBM(C25,"Market Cap","23-Jun-2026","23-Jun-2026","0","d","asc","USD","/1000000")} -> 72057.843 | E25: {=_xll.PBF(C25,"EV","TTM","23-Jun-2026","","USD","t")/1000000} -> 109440.61 | F25: {=_xll.PBF(C25,"Total Revenue","TTM","23-Jun-2026","","USD","t")/1000000} -> 42367 | G25: {=_xll.PBF(C25,"EBITDA","TTM","23-Jun-2026","","USD","t")/1000000} -> 7698 | H25: =IFERROR(G25/F25,"") -> 0.18169802 | I25: =IFERROR(E25/F25,"") -> 2.5831569 | J25: =IFERROR(E25/G25,"") -> 14.216758 | K25: {=_xll.PBF(C25,"Revenue % Growth","TTM","23-Jun-2026","","USD","t")} -> 0.049519421 | L25: PitchBook
A26: Aerospace | B26: RTX | C26: RTX | D26: {=_xll.PBM(C26,"Market Cap","23-Jun-2026","23-Jun-2026","0","d","asc","USD","/1000000")} -> 244867.45 | E26: {=_xll.PBF(C26,"EV","TTM","23-Jun-2026","","USD","t")/1000000} -> 293602.43 | F26: {=_xll.PBF(C26,"Total Revenue","TTM","23-Jun-2026","","USD","t")/1000000} -> 90373 | G26: {=_xll.PBF(C26,"EBITDA","TTM","23-Jun-2026","","USD","t")/1000000} -> 15360 | H26: =IFERROR(G26/F26,"") -> 0.16996227 | I26: =IFERROR(E26/F26,"") -> 3.2487848 | J26: =IFERROR(E26/G26,"") -> 19.114741 | K26: {=_xll.PBF(C26,"Revenue % Growth","TTM","23-Jun-2026","","USD","t")} -> 0.10562889 | L26: PitchBook
A27: Aerospace | B27: General Dynamics | C27: GD | D27: {=_xll.PBM(C27,"Market Cap","23-Jun-2026","23-Jun-2026","0","d","asc","USD","/1000000")} -> 92854.909 | E27: {=_xll.PBF(C27,"EV","TTM","23-Jun-2026","","USD","t")/1000000} -> 100415.72 | F27: {=_xll.PBF(C27,"Total Revenue","TTM","23-Jun-2026","","USD","t")/1000000} -> 53808 | G27: {=_xll.PBF(C27,"EBITDA","TTM","23-Jun-2026","","USD","t")/1000000} -> 6499 | H27: =IFERROR(G27/F27,"") -> 0.1207813 | I27: =IFERROR(E27/F27,"") -> 1.8661856 | J27: =IFERROR(E27/G27,"") -> 15.450949 | K27: {=_xll.PBF(C27,"Revenue % Growth","TTM","23-Jun-2026","","USD","t")} -> 0.093480735 | L27: PitchBook
A28: Aerospace | B28: L3Harris | C28: LHX | D28: {=_xll.PBM(C28,"Market Cap","23-Jun-2026","23-Jun-2026","0","d","asc","USD","/1000000")} -> 53248.686 | E28: {=_xll.PBF(C28,"EV","TTM","23-Jun-2026","","USD","t")/1000000} -> 74512.827 | F28: {=_xll.PBF(C28,"Total Revenue","TTM","23-Jun-2026","","USD","t")/1000000} -> 22477 | G28: {=_xll.PBF(C28,"EBITDA","TTM","23-Jun-2026","","USD","t")/1000000} -> 3850 | H28: =IFERROR(G28/F28,"") -> 0.1712862 | I28: =IFERROR(E28/F28,"") -> 3.3150699 | J28: =IFERROR(E28/G28,"") -> 19.353981 | K28: {=_xll.PBF(C28,"Revenue % Growth","TTM","23-Jun-2026","","USD","t")} -> 0.057940318 | L28: PitchBook
A29: Aerospace | B29: TransDigm | C29: TDG | D29: {=_xll.PBM(C29,"Market Cap","23-Jun-2026","23-Jun-2026","0","d","asc","USD","/1000000")} -> 72484.33 | E29: {=_xll.PBF(C29,"EV","TTM","23-Jun-2026","","USD","t")/1000000} -> 92975.601 | F29: {=_xll.PBF(C29,"Total Revenue","TTM","23-Jun-2026","","USD","t")/1000000} -> 9502 | G29: {=_xll.PBF(C29,"EBITDA","TTM","23-Jun-2026","","USD","t")/1000000} -> 4829 | H29: =IFERROR(G29/F29,"") -> 0.5082088 | I29: =IFERROR(E29/F29,"") -> 9.7848454 | J29: =IFERROR(E29/G29,"") -> 19.253593 | K29: {=_xll.PBF(C29,"Revenue % Growth","TTM","23-Jun-2026","","USD","t")} -> 0.13280877 | L29: PitchBook
A30: Aerospace | B30: HEICO | C30: HEI.A | D30: {=_xll.PBM(C30,"Market Cap","23-Jun-2026","23-Jun-2026","0","d","asc","USD","/1000000")} -> 38726.174 | E30: {=_xll.PBF(C30,"EV","TTM","23-Jun-2026","","USD","t")/1000000} -> 35310.433 | F30: {=_xll.PBF(C30,"Total Revenue","TTM","23-Jun-2026","","USD","t")/1000000} -> 4911.297 | G30: {=_xll.PBF(C30,"EBITDA","TTM","23-Jun-2026","","USD","t")/1000000} -> 1368.169 | H30: =IFERROR(G30/F30,"") -> 0.2785759 | I30: =IFERROR(E30/F30,"") -> 7.1896351 | J30: =IFERROR(E30/G30,"") -> 25.808532 | K30: {=_xll.PBF(C30,"Revenue % Growth","TTM","23-Jun-2026","","USD","t")} -> 0.18803891 | L30: PitchBook
A32: COMPS SUMMARY
A33: Connectivity median EV /Revenue | D33: =MEDIAN(I5:I8,I10:I11) -> 3.9829082
A34: Connectivity median EV /EBITDA | D34: =MEDIAN(J5,J7:J8,J10:J11) -> 10.46643
A35: Launch/Space Infra median EV/Revenue | D35: =MEDIAN(I14:I20) -> 11.291118
A36: Launch/Space Infra EV/Revenue
A37: A&D Median EV/Revenue | D37: =MEDIAN(I23:I30) -> 2.9159708
A38: A&D Median EV/EBITDA | D38: =MEDIAN(J23:J30) -> 19.184167
A39: Notes | D39: ASTS excluded from Connectivity median due to extreme EV/Revenue outlier; Launch EV/EBITDA not meaningful because most comps have negative EBITDA.

Sheet Segment SOTP
A1: SpaceX Segment SOTP Valuation
A3: Segment | B3: Revenue | C3: EBITDA | D3: Selected Metric | E3: Low Multiple | F3: Base Multiple | G3: High Multiple | H3: Low Value | I3: Base Value | J3: High Value | K3: Notes
A4: SEGMENT VALUATION
A5: Starlink/Connectivity | B5: 11387 | C5: 7168 | D5: Revenue | E5: 3.98 | F5: 6 | G5: 8 | H5: =B5*E5 -> 45320.26 | I5: =B5*F5 -> 68322 | J5: =B5*G5 -> 91096 | K5: Premium to connectivity median for growth / recurring revenue
A6: Space / Launch | B6: 4086 | C6: N/D | D6: Revenue | E6: 6 | F6: 11.3 | G6: 15 | H6: =B6*E6 -> 24516 | I6: =B6*F6 -> 46171.8 | J6: =B6*G6 -> 61290 | K6: Based on Launch / Space Infra comp range
A7: AI / xAI / Compute Infrastructure | B7: 3201 | C7: -1237 | D7: Revenue | E7: 3 | F7: 5 | G7: 7 | H7: =B7*E7 -> 9603 | I7: =B7*F7 -> 16005 | J7: =B7*G7 -> 22407 | K7: FY2025 AI segment revenue; EBITDA negative, valued on revenue
A8: Corporate/Other Adjustments | B8: N/M | C8: N/M | D8: Equity Value Adjustment | E8: 0 | F8: 0 | G8: 0 | H8: =E8 -> 0 | I8: =F8 -> 0 | J8: =G8 -> 0 | K8: Placeholder for corporate costs, minority interests, investments, or other adjustments if disclosed.
A10: ENTERPRISE VALUE SUMMARY
A11: Segment Enterprise Value | H11: =SUM(H5:H8) -> 79439.26 | I11: =SUM(I5:I8) -> 130498.8 | J11: =SUM(J5:J8) -> 174793 | K11: Sum of Segment Values
A12: Less: Net Debt (Cash) | H12: ='Deal Fact Sheet'!C50-'Deal Fact Sheet'!C49 -> -61741.06 | I12: =H12 -> -61741.06 | J12: =H12 -> -61741.06 | K12: Debt Minus Cash
A13: Implied Equity Value | H13: =H11-H12 -> 141180.32 | I13: =I11-I12 -> 192239.86 | J13: =J11-J12 -> 236534.06 | K13: Enterprise Value Minus Net Debt
A15: VALUATION COMPARISON
A16: IPO Equity value | I16: ='Deal Fact Sheet'!C47 -> 1776491.8 | K16: IPO valuation reference
A17: Day-1 Equity Value | I17: ='Deal Fact Sheet'!C55 -> 2117973 | K17: Day-1 trading valuation reference
A18: SOTP Base vs IPO Equity Value | I18: =I13/I16-1 -> -0.8917868 | K18: Premium / discount to IPO value
A19: SOTP Base vs DAY-1 Equity Value | I19: =I13/I17-1 -> -0.90923404 | K19: Premium / discount to Day-1 value
A21: SOTP CONCLUSION
A22: Based on corrected FY2025 disclosed segment data, the SOTP implies an equity value range of approximately $141.2bn to $236.5bn, with a base case of $192.2bn. This remains materially below the IPO and Day-1 equity values, indicating that the IPO valuation was not supported by current disclosed segment fundamentals alone and instead reflected significant embedded optionality around Starlink scale, Starship economics, AI / compute infrastructure, and long-term strategic value.

Sheet DCF Scenario
A1: SpaceX DCF Scenario Valuation
A3: Item | B3: 2026E | C3: 2027E | D3: 2028E | E3: 2029E | F3: 2030E | G3: Terminal | H3: Notes
A4: OPERATING FORECAST
A5: Revenue | B5: ='Deal Fact Sheet'!C25 -> 18674 | C5: =B5*(1+B6) -> 25209.9 | D5: =C5*(1+C6) -> 32772.87 | E5: =D5*(1+D6) -> 40966.088 | F5: =E5*(1+E6) -> 49159.305 | H5: Starts from latest FY revenue
A6: Revenue Growth | B6: 0.35 | C6: 0.3 | D6: 0.25 | E6: 0.2 | F6: 0.15 | H6: Growth rate shown produces the following year's revenue.
A7: EBITDA | B7: =B5*B8 -> 6535.9 | C7: =C5*C8 -> 9453.7125 | D7: =D5*D8 -> 13109.148 | E7: =E5*E8 -> 17410.587 | F7: =F5*F8 -> 22121.687 | H7: Revenue × EBITDA margin
A8: EBITDA Margin | B8: 0.35 | C8: 0.375 | D8: 0.4 | E8: 0.425 | F8: 0.45 | H8: Operating leverage
A9: Less: Taxes | B9: =B7*25% -> 1633.975 | C9: =C7*25% -> 2363.4281 | D9: =D7*25% -> 3277.287 | E9: =E7*25% -> 4352.6468 | F9: =F7*25% -> 5530.4218 | H9: Simplified tax on EBITDA
A10: Less: Capex | B10: =B5*B11 -> 20728.14 | C10: =C5*C11 -> 21428.415 | D10: =D5*D11 -> 11470.505 | E10: =E5*E11 -> 11265.674 | F10: =F5*F11 -> 11060.844 | H10: Revenue × capex %
A11: Capex% Revenue | B11: 1.11 | C11: 0.85 | D11: 0.35 | E11: 0.275 | F11: 0.225 | H11: Heavy reinvestment taper
A12: Less: Change in NWC | B12: =B5*B13 -> 560.22 | C12: =C5*C13 -> 756.297 | D12: =D5*D13 -> 819.32175 | E12: =E5*E13 -> 1024.1522 | F12: =F5*F13 -> 983.1861 | H12: Revenue × NWC %
A13: NWC% of Revenue | B13: 0.03 | C13: 0.03 | D13: 0.025 | E13: 0.025 | F13: 0.02 | H13: Simplified working capital
A14: Unlevered FCF | B14: =B7-B9-B10-B12 -> -16386.435 | C14: =C7-C9-C10-C12 -> -15094.428 | D14: =D7-D9-D10-D12 -> -2457.9653 | E14: =E7-E9-E10-E12 -> 768.11414 | F14: =F7-F9-F10-F12 -> 4547.2357 | H14: EBITDA - taxes - capex - NWC
A15: FCF Margin | B15: =B14/B5 -> -0.8775 | C15: =C14/C5 -> -0.59875 | D15: =D14/D5 -> -0.075 | E15: =E14/E5 -> 0.01875 | F15: =F14/F5 -> 0.0925 | H15: FCF / revenue
A17: DCF VALUATION
A18: Discount rate | B18: 0.12
A19: Terminal Growth rate | B19: 0.04
A20: Terminal Year FCF | B20: =F14 -> 4547.2357
A21: Terminal Value | B21: =B20*(1+B19)/(B18-B19) -> 59114.064
A22: PV of FCF | B22: =NPV(B18,B14:F14) -> -25345.088
A23: PV OF Terminal Value | B23: =B21/(1+B18)^5 -> 33542.908
A24: Implied Enterprise Value | B24: =B22+B23 -> 8197.8198
A25: Less: Net Debt/(Cash) | B25: ='Deal Fact Sheet'!C50-'Deal Fact Sheet'!C49 -> -61741.06
A26: Implied Equity Value | B26: =B24-B25 -> 69938.88
A27: Implied Equity Value / IPO | B27: =B26/'Deal Fact Sheet'!C47-1 -> -0.9606309
A28: Implied Equity Value vs Day-1 | B28: =B26/'Deal Fact Sheet'!C55-1 -> -0.96697839
A30: DCF Conclusion
A31: Under the current operating DCF case, SpaceX turns FCF-positive by 2029E as capex intensity normalizes, but the DCF implies a base equity value of approximately $69.9bn, materially below IPO and Day-1 market value. This suggests the simplified DCF does not capture the market’s embedded expectations for Starlink terminal scale, Starship optionality, defense/government growth, AI / compute infrastructure, and long-term margin expansion.
A36: DCF SENSITIVITY - IMPLIED EQUITY VALUE
A37: WACC / TERMINAL GROWTH | B37: 0.03 | C37: 0.035 | D37: 0.04 | E37: 0.045 | F37: 0.05
A38: 0.1 | B38: =NPV($A38,$B$14:$F$14)+(($F$14*(1+B$37))/($A38-B$37))/(1+$A38)^5-$B$25 -> 77416.396 | C38: =NPV($A38,$B$14:$F$14)+(($F$14*(1+C$37))/($A38-C$37))/(1+$A38)^5-$B$25 -> 80829.389 | D38: =NPV($A38,$B$14:$F$14)+(($F$14*(1+D$37))/($A38-D$37))/(1+$A38)^5-$B$25 -> 84811.214 | E38: =NPV($A38,$B$14:$F$14)+(($F$14*(1+E$37))/($A38-E$37))/(1+$A38)^5-$B$25 -> 89517.006 | F38: =NPV($A38,$B$14:$F$14)+(($F$14*(1+F$37))/($A38-F$37))/(1+$A38)^5-$B$25 -> 95163.957
A39: 0.11 | B39: =NPV($A39,$B$14:$F$14)+(($F$14*(1+B$37))/($A39-B$37))/(1+$A39)^5-$B$25 -> 70878.83 | C39: =NPV($A39,$B$14:$F$14)+(($F$14*(1+C$37))/($A39-C$37))/(1+$A39)^5-$B$25 -> 73375.001 | D39: =NPV($A39,$B$14:$F$14)+(($F$14*(1+D$37))/($A39-D$37))/(1+$A39)^5-$B$25 -> 76227.768 | E39: =NPV($A39,$B$14:$F$14)+(($F$14*(1+E$37))/($A39-E$37))/(1+$A39)^5-$B$25 -> 79519.421 | F39: =NPV($A39,$B$14:$F$14)+(($F$14*(1+F$37))/($A39-F$37))/(1+$A39)^5-$B$25 -> 83359.684
A40: 0.12 | B40: =NPV($A40,$B$14:$F$14)+(($F$14*(1+B$37))/($A40-B$37))/(1+$A40)^5-$B$25 -> 65925.199 | C40: =NPV($A40,$B$14:$F$14)+(($F$14*(1+C$37))/($A40-C$37))/(1+$A40)^5-$B$25 -> 67813.99 | D40: =NPV($A40,$B$14:$F$14)+(($F$14*(1+D$37))/($A40-D$37))/(1+$A40)^5-$B$25 -> 69938.88 | E40: =NPV($A40,$B$14:$F$14)+(($F$14*(1+E$37))/($A40-E$37))/(1+$A40)^5-$B$25 -> 72347.089 | F40: =NPV($A40,$B$14:$F$14)+(($F$14*(1+F$37))/($A40-F$37))/(1+$A40)^5-$B$25 -> 75099.327
A41: 0.13 | B41: =NPV($A41,$B$14:$F$14)+(($F$14*(1+B$37))/($A41-B$37))/(1+$A41)^5-$B$25 -> 62075.293 | C41: =NPV($A41,$B$14:$F$14)+(($F$14*(1+C$37))/($A41-C$37))/(1+$A41)^5-$B$25 -> 63543.138 | D41: =NPV($A41,$B$14:$F$14)+(($F$14*(1+D$37))/($A41-D$37))/(1+$A41)^5-$B$25 -> 65174.076 | E41: =NPV($A41,$B$14:$F$14)+(($F$14*(1+E$37))/($A41-E$37))/(1+$A41)^5-$B$25 -> 66996.89 | F41: =NPV($A41,$B$14:$F$14)+(($F$14*(1+F$37))/($A41-F$37))/(1+$A41)^5-$B$25 -> 69047.555
A42: 0.14 | B42: =NPV($A42,$B$14:$F$14)+(($F$14*(1+B$37))/($A42-B$37))/(1+$A42)^5-$B$25 -> 59023.765 | C42: =NPV($A42,$B$14:$F$14)+(($F$14*(1+C$37))/($A42-C$37))/(1+$A42)^5-$B$25 -> 60189.276 | D42: =NPV($A42,$B$14:$F$14)+(($F$14*(1+D$37))/($A42-D$37))/(1+$A42)^5-$B$25 -> 61471.337 | E42: =NPV($A42,$B$14:$F$14)+(($F$14*(1+E$37))/($A42-E$37))/(1+$A42)^5-$B$25 -> 62888.352 | F42: =NPV($A42,$B$14:$F$14)+(($F$14*(1+F$37))/($A42-F$37))/(1+$A42)^5-$B$25 -> 64462.813

Sheet Valuation Summary
A1: SpaceX Valuation Summary
A3: Method | B3: Low Equity value | C3: Base Equity Value | D3: High Equity Value | E3: Implied Vs IPO | F3: Implied Vs Day-1 | G3: Notes
A4: IPO Pricing | B4: ='Deal Fact Sheet'!C47 -> 1776491.8 | C4: ='Deal Fact Sheet'!C47 -> 1776491.8 | D4: ='Deal Fact Sheet'!C47 -> 1776491.8 | E4: =0 -> 0 | F4: =C4/'Deal Fact Sheet'!C55-1 -> -0.1612302 | G4: IPO offer price valuation
A5: Day-1 Trading | B5: ='Deal Fact Sheet'!C55 -> 2117973 | C5: ='Deal Fact Sheet'!C55 -> 2117973 | D5: ='Deal Fact Sheet'!C55 -> 2117973 | E5: =C5/'Deal Fact Sheet'!C47-1 -> 0.19222222 | F5: 0 | G5: First close market valuation
A6: Segment SOTP | B6: ='Segment SOTP'!H13 -> 141180.32 | C6: ='Segment SOTP'!I13 -> 192239.86 | D6: ='Segment SOTP'!J13 -> 236534.06 | E6: =C6/'Deal Fact Sheet'!C47-1 -> -0.8917868 | F6: =C6/'Deal Fact Sheet'!C55-1 -> -0.90923404 | G6: FY2025 disclosed segment SOTP; excludes embedded optionality
A7: DCF | B7: =MIN('DCF Scenario'!B38:F42) -> 59023.765 | C7: ='DCF Scenario'!D40 -> 69938.88 | D7: =MAX('DCF Scenario'!B38:F42) -> 95163.957 | E7: =C7/'Deal Fact Sheet'!C47-1 -> -0.9606309 | F7: =C7/'Deal Fact Sheet'!C55-1 -> -0.96697839 | G7: Simplified operating DCF
A8: Trading Comps | G8: Use as reference, not direct valuation unless applying multiples
A11: Football Field Data
A12: Method | B12: Range Start | C12: Range Width | D12: Low | E12: Base | F12: High | G12: Notes
A13: IPO Pricing | B13: =0 -> 0 | C13: =D4-B4 -> 0 | D13: =B4 -> 1776491.8 | E13: =C4 -> 1776491.8 | F13: =D4 -> 1776491.8 | G13: IPO Pricing Point
A14: Day-1 Trading | B14: =0 -> 0 | C14: =D5-B5 -> 0 | D14: =B5 -> 2117973 | E14: =C5 -> 2117973 | F14: =D5 -> 2117973 | G14: First close Point
A15: Segment SOTP | B15: =0 -> 0 | C15: =F15-D15 -> 95353.74 | D15: ='Segment SOTP'!H13 -> 141180.32 | E15: ='Segment SOTP'!I13 -> 192239.86 | F15: ='Segment SOTP'!J13 -> 236534.06 | G15: FY2025 disclosed segment SOTP; excludes embedded optionality
A16: DCF | B16: =0 -> 0 | C16: =D7-B7 -> 36140.192 | D16: =B7 -> 59023.765 | E16: =C7 -> 69938.88 | F16: =D7 -> 95163.957 | G16: DCF Sensitivity Range
A35: VALUATION SUMMARY CONCLUSION
A36: The valuation work indicates a substantial gap between current disclosed fundamentals and the IPO / Day-1 market valuation. SOTP and DCF outputs remain materially below public-market pricing, even after correcting FY2025 segment data and pro forma cash treatment. The post-IPO valuation therefore appears driven less by near-term financials and more by investor expectations for long-duration growth, platform optionality, and strategic scarcity value.

Sheet Deal Structure
A1: SpaceX Deal Structure
A3: Item | B3: Value | C3: Units | D3: Source | E3: Confidence | F3: Notes
A4: OFFERING STRUCTURE
A5: IPO Price | B5: ='Deal Fact Sheet'!C10 -> 135 | C5: $ / share | D5: 424B4 / Pricing Announcement | E5: H | F5: Final price at which IPO investors purchased shares.
A6: Shares Offered | B6: ='Deal Fact Sheet'!C11 -> 555.556 | C6: mm shares | D6: 424B4 / Pricing Announcement | E6: H | F6: Base number of shares sold in the IPO before any overallotment exercise.
A7: Gross Proceeds | B7: =B5*B6 -> 75000.06 | C7: $mm | D7: Formula | E7: H | F7: Total capital raised before underwriting discounts, commissions, and offering expenses.
A8: Greenshoe/Overallotment Shares | B8: ='Deal Fact Sheet'!C13 -> 83.33 | C8: mm shares | D8: 424B4 | E8: H/M | F8: Optional additional shares underwriters may purchase to support stabilization and meet excess demand.
A9: Total Proceeds Incl. Greenshoe | B9: =IF(B8="N/D","N/D",B7+B8*B5) -> 86249.61 | C9: $mm | D9: Formula / 424B4 | E9: H/M | F9: Maximum gross proceeds assuming the overallotment option is fully exercised.
A10: Primary Shares | B10: =B6 -> 555.556 | C10: mm shares | D10: 424B4 | E10: H | F10: New shares issued by the company, with proceeds going to the issuer.
A11: Secondary Shares | B11: 0 | C11: mm shares | D11: 424B4 | E11: H | F11: Existing shares sold by current holders, with proceeds going to selling shareholders rather than the company.
A12: Primary/Secondary Mix | B12: =TEXT(B10/(B10+B11),"0.0%")&" primary / "&TEXT(B11/(B10+B11),"0.0%")&" secondary" -> 100.0% primary / 0.0% secondary | C12: % | D12: Formula / 424B4 | E12: H | F12: Shows whether the IPO was primarily a capital-raising event or a liquidity event.
A13: Total Diluted Shares Outstanding | B13: ='Deal Fact Sheet'!C46 -> 13159.199 | C13: mm shares | D13: 424B4 | E13: H | F13: Share count used to calculate fully diluted equity value after the IPO.
A14: Free Float% | B14: =B6/B13 -> 0.042218073 | C14: % | D14: Formula | E14: H | F14: Measures the portion of diluted shares initially available for public trading.
A15: IPO Equity Value | B15: ='Deal Fact Sheet'!C47 -> 1776491.8 | C15: $mm | D15: Formula | E15: H | F15: Fully diluted market value implied by the IPO offer price.
A16: Pro Forma Enterprise Value | B16: ='Deal Fact Sheet'!C51 -> 1714750.7 | C16: $mm | D16: Formula / 424B4 | E16: H | F16: Operating value of the company after adjusting equity value for debt and pro forma cash.
A17: Lead Underwriters | B17: Goldman Sachs/Morgan Stanley /BofA/Citigroup/J.P. Morgan | C17: Text | D17: 424B4 | E17: H | F17: Banks responsible for leading execution, bookbuilding, pricing, and distribution.
A19: GOVERNANCE/SHARE CLASS
A20: Share Classes | B20: Class A common stock and Class B common stock | C20: Text | D20: 424B4 | E20: H | F20: Defines the company’s equity structure and whether voting rights differ across share classes.
A21: Public Share Class | B21: Class A common stock | C21: Text | D21: 424B4 | E21: H | F21: Class of stock sold to public IPO investors.
A22: Founder/Musk Voting Control | B22: 82.3% voting power if overallotment exercised in full | C22: % / Text | D22: 424B4 | E22: H/M | F22: Measures the extent of founder or insider control after the public listing.
A23: Super-Voting Rights | B23: Class B: 10 votes per share; Class A: 1 vote per share | C23: votes / share | D23: 424B4 | E23: H | F23: High-vote shares can preserve insider control despite reduced economic ownership.
A24: Public Shareholder Voting Rights | B24: 1 vote per Class A share | C24: votes / share | D24: 424B4 | E24: H | F24: Voting power received by public IPO investors.
A25: Lock-Up Period | B25: 366 days | C25: days | D25: 424B4 | E25: H | F25: Restriction period limiting insider or selling-holder share sales after the IPO.
A26: Lock-Up Parties | B26: Musk, insiders, directors, officers, employees, and selling holders | C26: Text | D26: 424B4 | E26: H/M | F26: Groups restricted from selling shares during the lock-up period.
A27: Governance Implications | B27: Founder control preserved despite public listing | C27: Text | D27: Model Judgment | E27: M | F27: Summary of how the share structure affects public-market governance.
A29: ALLOCATION/DEMAND
A30: Book Oversubscription | B30: 4x | C30: x | D30: Pricing Commentary / Offering Materials | E30: M/H | F30: Demand indicator showing how many times investor orders exceeded available shares.
A31: Anchor Investor Allocation | B31: N/D | C31: $mm / % | D31: 424B4 / Offering Materials | E31: M | F31: Pre-committed institutional demand that can support book quality and pricing confidence.
A32: Retail Allocation | B32: N/D | C32: Text | D32: Offering Materials | E32: M | F32: Public or brokerage-based access provided to non-institutional investors.
A33: First Trade/Open Price | B33: 150 | C33: $ / share | D33: Market Data | E33: H | F33: First public trading level and initial market-clearing signal.
A34: Day-1 Close | B34: ='Aftermarket Trading '!C5 -> 160.95 | C34: $ / share | D34: Market Data | E34: H | F34: Final first-day trading price used to judge aftermarket performance.
A35: Day-1 Pop | B35: ='Aftermarket Trading '!D5 -> 0.19222222 | C35: % | D35: Formula / Market Data | E35: H | F35: Percentage gain from IPO price to first-day close, indicating underpricing or demand strength.
A36: Money Left On the Table | B36: ='Deal Fact Sheet'!C58 -> 14416.678 | C36: $mm | D36: Formula / Market Data | E36: H | F36: Value transferred to IPO buyers because shares traded above the offer price.
A38: DEAL STRUCTURE CONCLUSION
A39: SpaceX’s IPO structure combined record primary issuance, limited public float, strong institutional demand, founder-control protections, lock-up constraints, and a green-shoe mechanism to support aftermarket stabilization. The structure appears designed to maximize capital raised while preserving strategic control and creating scarcity value in the public float.

Sheet Use Of Proceeds 
A1: SpaceX Use of Proceeds
A3: Item | B3: Value | C3: Units | D3: Source | E3: Confidence | F3: Notes
A4: IPO PROCEEDS BRIDGE
A5: Gross IPO Proceeds | B5: ='Deal Fact Sheet'!C12 -> 75000.06 | C5: $mm | D5: Formula / 424B4 | E5: H | F5: Total capital raised before underwriting discounts, commissions, offering expenses, and any overallotment impact.
A6: Gross Proceeds incl. Greenshoe | B6: ='Deal Structure'!B9 -> 86249.61 | C6: $mm | D6: Formula / 424B4 | E6: H/M | F6: Represents maximum gross proceeds if the overallotment option is exercised in full.
A7: Underwriting Discounts/Fees | B7: =0.9*'Deal Fact Sheet'!C11 -> 500.0004 | C7: $mm | D7: 424B4 | E7: M | F7: Fees paid to underwriters for structuring, marketing, bookbuilding, and distributing the IPO.
A8: Offering Expense | B8: N/D | C8: $mm | D8: 424B4 | E8: M | F8: Issuer-paid legal, accounting, listing, filing, printing, and other transaction expenses.
A9: Estimated Net Proceeds | B9: =B5-B7 -> 74500.06 | C9: $mm | D9: Formula | E9: M | F9: Cash proceeds available to the company after deducting underwriting fees and offering expenses.
A10: Primary Proceeds to Company | B10: =IF('Deal Structure'!B10="N/D","N/D",'Deal Structure'!B10*'Deal Structure'!B5) -> 75000.06 | C10: $mm | D10: Formula / 424B4 | E10: H | F10: Cash raised by issuing new shares, directly strengthening the company’s balance sheet.
A11: Secondary Proceeds to Selling Holders | B11: =IF('Deal Structure'!B11="N/D","N/D",'Deal Structure'!B11*'Deal Structure'!B5) -> 0 | C11: $mm | D11: Formula / 424B4 | E11: H | F11: Proceeds received by existing shareholders if they sold shares in the IPO.
A13: STATED USE OF PROCEEDS
A14: Starship Development/ Launch Infrastructure | B14: N/D | C14: Text | D14: 424B4 | E14: M | F14: Use-of-proceeds category for launch-system development, manufacturing scale-up, and infrastructure expansion if specifically disclosed.
A15: Starlink Satelliete Constellation Capex | B15: N/D | C15: Text | D15: 424B4 | E15: M | F15: Use-of-proceeds category for satellite deployment, network expansion, ground infrastructure, and related constellation investment if specifically disclosed.
A16: AI/xAI/Computer Infrastructure | B16: N/D | C16: Text | D16: 424B4 | E16: M | F16: Use-of-proceeds category for AI, compute, data-center, or related infrastructure investment if specifically disclosed.
A17: General Corporate Purposes | B17: N/D | C17: Text | D17: 424B4 | E17: M | F17: Broad use category that gives management flexibility over capital deployment.
A18: Working Capital | B18: N/D | C18: Text | D18: 424B4 | E18: M | F18: Funding available for near-term operating needs, inventory, receivables, and business expansion.
A19: Debt Repayment | B19: N/D | C19: Text | D19: 424B4 | E19: M | F19: Indicates whether IPO proceeds were used to reduce leverage or refinance existing obligations.
A20: Acquisitions/Startegic Investments | B20: N/D | C20: Text | D20: 424B4 | E20: M | F20: Indicates whether proceeds may fund external growth, partnerships, or strategic investments.
A21: Other Disclosed Uses | B21: N/D | C21: Text | D21: 424B4 | E21: M | F21: Captures any additional use-of-proceeds language not covered by the main categories.
A23: CAPEX CONTEXT
A24: FY 2025 Capex | B24: ='Deal Fact Sheet'!C31 -> 20737 | C24: $mm | D24: 424B4 | E24: H | F24: Historical capital spending baseline used to assess the scale of the IPO proceeds.
A25: FY 2025 Revenue | B25: ='Deal Fact Sheet'!C25 -> 18674 | C25: $mm | D25: 424B4 | E25: H | F25: Revenue base used to contextualize the size of the offering relative to the business.
A26: Capex as % of Revenue | B26: =B24/B25 -> 1.1104745 | C26: % | D26: Formula | E26: H | F26: Measures capital intensity and indicates how much revenue is reinvested into infrastructure and growth.
A27: IPO Proceeds/FY 2025 Capex | B27: =B5/B24 -> 3.6167266 | C27: x | D27: Formula | E27: H | F27: Shows how many years of FY2025-level capital spending the IPO could theoretically fund.
A28: IPO Proceeds/FY 2026 Revenue | B28: =B5/B25 -> 4.0162825 | C28: x | D28: Formula | E28: H | F28: Shows the scale of IPO proceeds relative to the company’s annual revenue base.
A29: Pro Forma Cash after IPO | B29: ='Deal Fact Sheet'!C49 -> 90852.06 | C29: $mm | D29: Formula / 424B4 | E29: H | F29: Cash balance after giving effect to the offering, before future deployment.
A30: Net Cash/ Debt position after IPO | B30: ='Deal Fact Sheet'!C50-B29 -> -61741.06 | C30: $mm | D30: Formula / 424B4 | E30: H | F30: Indicates whether the company has net cash or net debt after the IPO capitalization.
A32: USE OF PROCEEDS CONCLUSION
A33: The IPO proceeds materially strengthened SpaceX’s balance sheet and provided substantial funding capacity for capex-intensive growth initiatives. Given FY2025 capex intensity, the offering appears designed less as a liquidity event and more as a strategic capitalization event to support long-duration infrastructure investment, including areas such as launch capacity, satellite deployment, AI / compute infrastructure, and general corporate purposes.

Sheet Risk Factors
A1: SpaceX IPO Risk Factors
A3: Risk Category | B3: Risk Factor | C3: Prospectus / Filing Summary | D3: Evidence / Metric | E3: Severity | F3: Market Discounted? | G3: Mitigant / Equity Story | H3: Source | I3: Confidence | J3: Notes
A4: CORE PROSPECTUS RISK FACTORS
A5: Commercial / Customer | B5: Customer concentration | C5: Revenue may depend on a concentrated set of government, commercial, and strategic customers. | D5: N/D unless exact customer concentration is disclosed. | E5: H | F5: Partially | G5: Mission-critical services and government-linked demand support revenue durability. | H5: 424B4 / Prospectus | I5: M | J5: Large contract losses could materially affect revenue visibility.
A6: Regulatory | B6: Regulatory approval / launch licensing | C6: Launch operations depend on regulatory approvals, licenses, safety reviews, and ongoing compliance. | D6: FAA / FCC / government approvals required for launch and satellite operations. | E6: H | F6: Partially | G6: Operating history and strategic national importance reduce perceived approval risk. | H6: 424B4 / Prospectus | I6: H | J6: Regulatory delays can directly constrain launch cadence and revenue conversion.
A7: Operations / Execution | B7: Launch cadence and execution risk | C7: Business performance depends on maintaining high launch reliability, cadence, and operational execution. | D7: N/D unless exact launch cadence is disclosed. | E7: H | F7: Partially | G7: Proven launch track record supports investor confidence in execution. | H7: 424B4 / Prospectus | I7: M | J7: Execution risk is central because valuation assumes continued scale and reliability.
A8: Technology / Development | B8: Starship Development Risk | C8: Future growth may depend on successful development, testing, certification, and commercialization of Starship. | D8: N/D unless specific Starship milestones are disclosed. | E8: H | F8: No | G8: Successful Starship execution could materially expand launch capacity and lower cost per mission. | H8: 424B4 / Prospectus | I8: M | J8: High-upside but high-risk development program embedded in the equity story.
A9: Operations / Capex | B9: Starlink constellation deployment risk | C9: Starlink growth depends on satellite deployment, network capacity, ground infrastructure, and customer adoption. | D9: N/D unless exact deployment metrics are disclosed. | E9: H | F9: Partially | G9: Recurring revenue profile and global broadband demand support the Starlink growth narrative. | H9: 424B4 / Prospectus | I9: M | J9: Starlink execution is a major driver of the company’s growth multiple.
A10: Regulatory / Space | B10: Spectrum, satellite, and orbital debris regulation | C10: Satellite operations are subject to spectrum rights, orbital constraints, debris mitigation, and international regulation. | D10: FCC / international satellite and spectrum regulation. | E10: M | F10: Partially | G10: Existing operating scale and regulatory experience help mitigate compliance risk. | H10: 424B4 / Prospectus | I10: H | J10: Regulation can affect deployment pace, service quality, and expansion into new markets.
A11: Financial / Capex | B11: Capex intensity and cash burn | C11: Growth strategy requires substantial ongoing investment in launch systems, satellites, infrastructure, and compute capacity. | D11: ="FY2025 capex: $"&TEXT('Use Of Proceeds '!B24,"#,##0")&"mm; capex/revenue: "&TEXT('Use Of Proceeds '!B26,"0.0%") -> FY2025 capex: $20,737mm; capex/revenue: 111.0% | E11: H | F11: Partially | G11: IPO proceeds materially increase funding capacity for long-duration growth investment. | H11: Formula / Workbook | I11: H | J11: Capex intensity is a core risk because valuation depends on funding large infrastructure programs.
A12: Financial / Profitability | B12: Losses / profitability risk | C12: The company may continue to incur losses due to growth investment, R&D, capex, and operating scale-up costs. | D12: ="Loss from operations: $"&TEXT('Deal Fact Sheet'!C30,"#,##0")&"mm; Adj. EBITDA: $"&TEXT('Deal Fact Sheet'!C29,"#,##0")&"mm" -> Loss from operations: $-2,589mm; Adj. EBITDA: $6,584mm | E12: H | F12: Partially | G12: Investors may accept near-term losses if revenue growth and long-term margin potential remain strong. | H12: 424B4 / Prospectus / Formula / Workbook | I12: M | J12: Profitability risk matters because public-market valuation must eventually be supported by earnings power.
A13: Technology / AI | B13: AI / compute infrastructure investment risk | C13: Investment in AI, compute, and related infrastructure may increase losses and execution complexity. | D13: N/D unless exact AI / compute spending is disclosed. | E13: M | F13: No | G13: AI and compute infrastructure may create strategic optionality if deployed effectively. | H13: 424B4 / Prospectus | I13: M | J13: Frame this as optionality with uncertain near-term return on invested capital.
A14: Key Person / Governance | B14: Musk key-person risk | C14: Company strategy, investor perception, and execution may be materially influenced by Elon Musk. | D14: N/D unless exact key-person disclosure is available. | E14: H | F14: Partially | G14: Founder-led narrative supports premium valuation but creates governance and succession risk. | H14: 424B4 / Prospectus | I14: H | J14: Key-person risk is especially relevant given the founder’s influence across strategy and market perception.
A15: Governance | B15: Founder control / governance risk | C15: Voting structure may limit public shareholder influence over major corporate decisions. | D15: ="Voting control: "&'Deal Structure'!B22&"; "&'Deal Structure'!B23 -> Voting control: 82.3% voting power if overallotment exercised in full; Class B: 10 votes per share; Class A: 1 vote per share | E15: H | F15: Yes | G15: Investors accepted governance limitations in exchange for founder-led growth exposure. | H15: 424B4 / Prospectus / Formula / Workbook | I15: H | J15: Governance risk is structurally important but common in founder-controlled growth IPOs.
A16: Supply Chain / Manufacturing | B16: Supply chain and manufacturing risk | C16: Operations depend on complex manufacturing, specialized components, suppliers, and production scaling. | D16: N/D unless exact supplier concentration is disclosed. | E16: M | F16: Partially | G16: Vertical integration may reduce supplier dependence and improve execution control. | H16: 424B4 / Prospectus | I16: M | J16: Supply constraints could affect launch cadence, satellite deployment, and cost structure.
A17: Competitive Landscape | B17: Competition in launch, satellite broadband, and defense / aerospace markets | C17: The company competes with satellite operators, telecom providers, aerospace primes, and launch competitors. | D17: N/D unless market-share data is disclosed. | E17: M | F17: Partially | G17: Scale, brand, launch economics, and integrated ecosystem support competitive differentiation. | H17: 424B4 / Prospectus | I17: M | J17: Competition matters, but investors may underwrite SpaceX as a category leader.
A19: MARKET DISCOUNT / EQUITY STORY
A20: Market Perception | B20: Risks market appeared to discount | C20: Strong first-day trading suggests investors were willing to absorb major execution, governance, and capex risks. | D20: ="Day-1 close: $"&TEXT('Aftermarket Trading '!C5,"0.00")&"; Day-1 pop: "&TEXT('Aftermarket Trading '!D5,"0.0%") -> Day-1 close: $160.95; Day-1 pop: 19.2% | E20: M | F20: Yes | G20: Demand strength indicated confidence in long-term growth and strategic scarcity value. | H20: Market Data / Formula / Workbook | I20: H | J20: Aftermarket performance suggests risk appetite remained strong despite prospectus disclosures.
A21: Market Perception | B21: Risks market may be underpricing | C21: Market may be underpricing development, regulatory, capex, and key-person risks relative to the valuation premium. | D21: ="IPO equity value: $"&TEXT('Valuation Summary'!C4/1000,"#,##0.0")&"bn; SOTP base vs IPO: "&TEXT('Valuation Summary'!E6,"0.0%") -> IPO equity value: $1,776.5bn; SOTP base vs IPO: -89.2% | E21: H | F21: No | G21: Premium valuation reflects scarcity, growth optionality, and strategic importance. | H21: Model Judgment / Formula / Workbook | I21: M | J21: Judgment-based row; do not overstate certainty.
A22: Valuation | B22: Risks most relevant to valuation multiple | C22: Capex intensity, Starlink growth, Starship execution, profitability, and launch cadence are most relevant to sustaining valuation. | D22: ="IPO EV/revenue: "&TEXT('Deal Fact Sheet'!C52,"0.0x")&"; SOTP base equity value: $"&TEXT('Segment SOTP'!I13/1000,"#,##0.0")&"bn" -> IPO EV/revenue: 91.8x; SOTP base equity value: $192.2bn | E22: H | F22: Partially | G22: Investors appear to value long-term platform potential rather than near-term earnings alone. | H22: Model Judgment / Formula / Workbook | I22: M | J22: These risks directly affect whether SpaceX can justify a premium public-market multiple.
A23: IPO Structure / Governance | B23: Risks most relevant to IPO structure | C23: Founder control, limited float, lock-up restrictions, allocation dynamics, and governance rights shaped the IPO structure. | D23: ="Free float: "&TEXT('Deal Structure'!B14,"0.0%")&"; voting control: "&'Deal Structure'!B22&"; lock-up: "&'Deal Structure'!B25 -> Free float: 4.2%; voting control: 82.3% voting power if overallotment exercised in full; lock-up: 366 days | E23: M | F23: Yes | G23: Scarce float and strong demand may have supported aftermarket performance. | H23: 424B4 / Prospectus / Formula / Workbook | I23: H | J23: Structure risk matters because public investors may have limited control and limited initial float.
A24: Equity Story | B24: Key mitigants supporting investor demand | C24: Investor demand was supported by leadership in launch, Starlink growth, strategic importance, and long-term optionality. | D24: ="Day-1 pop: "&TEXT('Aftermarket Trading '!D5,"0.0%")&"; oversubscription: "&'Deal Structure'!B30&"; IPO equity value: $"&TEXT('Valuation Summary'!C4/1000,"#,##0.0")&"bn" -> Day-1 pop: 19.2%; oversubscription: 4x; IPO equity value: $1,776.5bn | E24: M | F24: Yes | G24: Scarcity value, category leadership, and growth optionality helped offset disclosed risks. | H24: Market Data / Model Judgment / Formula / Workbook | I24: M | J24: Summarizes why the market accepted the risk profile.
A26: RISK FACTOR CONCLUSION
